Process A [NEW] (arrival time 9 ms) 16 CPU bursts
Process B [NEW] (arrival time 18 ms) 21 CPU bursts
Process C [NEW] (arrival time 84 ms) 82 CPU bursts
Process D [NEW] (arrival time 86 ms) 36 CPU bursts
Process E [NEW] (arrival time 2 ms) 26 CPU bursts
Process F [NEW] (arrival time 25 ms) 39 CPU bursts
Process G [NEW] (arrival time 13 ms) 76 CPU bursts
Process H [NEW] (arrival time 46 ms) 82 CPU bursts
Process I [NEW] (arrival time 64 ms) 63 CPU bursts
Process J [NEW] (arrival time 31 ms) 21 CPU bursts
Process K [NEW] (arrival time 56 ms) 1 CPU bursts
Process L [NEW] (arrival time 12 ms) 3 CPU bursts
time 0ms: Simulator started for SJF [Q <empty>]
time 2ms: Process E (tau 100ms) arrived; added to ready queue [Q E]
time 4ms: Process E started using the CPU for 11ms burst [Q <empty>]
time 9ms: Process A (tau 100ms) arrived; added to ready queue [Q A]
time 12ms: Process L (tau 100ms) arrived; added to ready queue [Q A L]
time 13ms: Process G (tau 100ms) arrived; added to ready queue [Q A L G]
time 15ms: Process E completed a CPU Burst; 25 bursts to go [Q A L G]
time 15ms: Recalculate tau = 56ms for Process E [Q A L G]
time 15ms: Process E switching out of CPU; will block on I/O until time 34ms
time 18ms: Process B (tau 100ms) arrived; added to ready queue [Q L G B]
time 19ms: Process A started using the CPU for 56ms burst [Q L G B]
time 25ms: Process F (tau 100ms) arrived; added to ready queue [Q L G B F]
time 31ms: Process J (tau 100ms) arrived; added to ready queue [Q L G B F J]
time 34ms: Process E (tau 56ms) completed I/O; added to ready queue[Q L G B F J E]
time 46ms: Process H (tau 100ms) arrived; added to ready queue [Q L G B F J E H]
time 56ms: Process K (tau 100ms) arrived; added to ready queue [Q J E H K B F G L]
time 64ms: Process I (tau 100ms) arrived; added to ready queue [Q J E H K I B F L G]
time 75ms: Process A completed a CPU Burst; 15 bursts to go [Q G H K J E F L I B]
time 75ms: Recalculate tau = 78ms for Process A [Q G H K J E F L I B]
time 75ms: Process A switching out of CPU; will block on I/O until time 100ms
time 79ms: Process B started using the CPU for 106ms burst [Q G H J K E F I L]
time 84ms: Process C (tau 100ms) arrived; added to ready queue [Q F E L I C K J H G]
time 86ms: Process D (tau 100ms) arrived; added to ready queue [Q L I F E D C K H G J]
time 100ms: Process A (tau 78ms) completed I/O; added to ready queue[Q L I E D F A C K H J G]
time 185ms: Process B completed a CPU Burst; 20 bursts to go [Q H G L I J E D A C F K]
time 185ms: Recalculate tau = 103ms for Process B [Q H G L I J E D A C F K]
time 185ms: Process B switching out of CPU; will block on I/O until time 343ms
time 189ms: Process K started using the CPU for 37ms burst [Q H G J I L E D F C A]
time 226ms: Process K terminated [Q H G J I L E D F C A]
time 230ms: Process E started using the CPU for 65ms burst [Q I A F D C L J H G]
time 295ms: Process E completed a CPU Burst; 24 bursts to go [Q G F D I A J H C L]
time 295ms: Recalculate tau = 61ms for Process E [Q G F D I A J H C L]
time 295ms: Process E switching out of CPU; will block on I/O until time 352ms
time 299ms: Process L started using the CPU for 133ms burst [Q G F I D A J C H]
time 343ms: Process B (tau 103ms) completed I/O; added to ready queue[Q F G D I B J A C H]
time 352ms: Process E (tau 61ms) completed I/O; added to ready queue[Q G D I B E C H A F J]
time 432ms: Process L completed a CPU Burst; 2 bursts to go [Q G D B E I C H F J A]
time 432ms: Recalculate tau = 117ms for Process L [Q G D B E I C H F J A]
time 432ms: Process L switching out of CPU; will block on I/O until time 564ms
time 436ms: Process G started using the CPU for 76ms burst [Q F I B D E J A C H]
time 512ms: Process G completed a CPU Burst; 75 bursts to go [Q J D F H B C E I A]
time 512ms: Recalculate tau = 88ms for Process G [Q J D F H B C E I A]
time 512ms: Process G switching out of CPU; will block on I/O until time 657ms
time 516ms: Process A started using the CPU for 60ms burst [Q J D H F B C I E]
time 564ms: Process L (tau 117ms) completed I/O; added to ready queue[Q J D H F L B C E I]
time 576ms: Process A completed a CPU Burst; 14 bursts to go [Q D C E L B F J I H]
time 576ms: Recalculate tau = 69ms for Process A [Q D C E L B F J I H]
time 576ms: Process A switching out of CPU; will block on I/O until time 731ms
time 580ms: Process H started using the CPU for 9ms burst [Q D C L E B F I J]
time 589ms: Process H completed a CPU Burst; 81 bursts to go [Q B F I J L E C D]
time 589ms: Recalculate tau = 55ms for Process H [Q B F I J L E C D]
time 589ms: Process H switching out of CPU; will block on I/O until time 770ms
time 593ms: Process I started using the CPU for 190ms burst [Q J F B C D E L]
time 657ms: Process G (tau 88ms) completed I/O; added to ready queue[Q D E L G B C F J]
time 731ms: Process A (tau 69ms) completed I/O; added to ready queue[Q L G E D A F J B C]
time 770ms: Process H (tau 55ms) completed I/O; added to ready queue[Q J B A F H C E L G D]
time 783ms: Process I completed a CPU Burst; 62 bursts to go [Q C E L G D J B F H A]
time 783ms: Recalculate tau = 145ms for Process I [Q C E L G D J B F H A]
time 783ms: Process I switching out of CPU; will block on I/O until time 920ms
time 787ms: Process C started using the CPU for 79ms burst [Q F D L E G H A J B]
time 866ms: Process C completed a CPU Burst; 81 bursts to go [Q E G D L J B H A F]
time 866ms: Recalculate tau = 90ms for Process C [Q E G D L J B H A F]
time 866ms: Process C switching out of CPU; will block on I/O until time 1025ms
time 870ms: Process F started using the CPU for 24ms burst [Q E G L D J B A H]
time 894ms: Process F completed a CPU Burst; 38 bursts to go [Q E G L D J B A H]
time 894ms: Recalculate tau = 62ms for Process F [Q E G L D J B A H]
time 894ms: Process F switching out of CPU; will block on I/O until time 962ms
time 898ms: Process L started using the CPU for 71ms burst [Q D G E A H B J]
time 920ms: Process I (tau 145ms) completed I/O; added to ready queue[Q H B J I E A G D]
time 962ms: Process F (tau 62ms) completed I/O; added to ready queue[Q J I B H F G D E A]
time 969ms: Process L completed a CPU Burst; 1 bursts to go [Q H F I B E A G D J]
time 969ms: Recalculate tau = 94ms for Process L [Q H F I B E A G D J]
time 969ms: Process L switching out of CPU; will block on I/O until time 1039ms
time 973ms: Process J started using the CPU for 97ms burst [Q H F B I E A D G]
time 1025ms: Process C (tau 90ms) completed I/O; added to ready queue[Q F H I B C A E D G]
time 1039ms: Process L (tau 94ms) completed I/O; added to ready queue[Q D C H E L A B G I F]
time 1070ms: Process J completed a CPU Burst; 20 bursts to go [Q A B G I F D C E L H]
time 1070ms: Recalculate tau = 99ms for Process J [Q A B G I F D C E L H]
time 1070ms: Process J switching out of CPU; will block on I/O until time 1163ms
time 1074ms: Process A started using the CPU for 39ms burst [Q E F G B I L H D C]
time 1113ms: Process A completed a CPU Burst; 13 bursts to go [Q F H D I L B E C G]
time 1113ms: Recalculate tau = 54ms for Process A [Q F H D I L B E C G]
time 1113ms: Process A switching out of CPU; will block on I/O until time 1165ms
time 1117ms: Process G started using the CPU for 184ms burst [Q F H I D L B C E]
time 1163ms: Process J (tau 99ms) completed I/O; added to ready queue[Q D I F H J E C B L]
time 1165ms: Process A (tau 54ms) completed I/O; added to ready queue[Q F H D I A J E B L C]
time 1301ms: Process G completed a CPU Burst; 74 bursts to go [Q F H A D I J E C B L]
time 1301ms: Recalculate tau = 136ms for Process G [Q F H A D I J E C B L]
time 1301ms: Process G switching out of CPU; will block on I/O until time 1335ms
time 1305ms: Process F started using the CPU for 15ms burst [Q C I A H D B L J E]
time 1320ms: Process F completed a CPU Burst; 37 bursts to go [Q L C E B H D I A J]
time 1320ms: Recalculate tau = 39ms for Process F [Q L C E B H D I A J]
time 1320ms: Process F switching out of CPU; will block on I/O until time 1402ms
time 1324ms: Process J started using the CPU for 39ms burst [Q L C B E H D A I]
time 1335ms: Process G (tau 136ms) completed I/O; added to ready queue[Q A I D H G C L B E]
time 1363ms: Process J completed a CPU Burst; 19 bursts to go [Q G C L B E D H A I]
time 1363ms: Recalculate tau = 69ms for Process J [Q G C L B E D H A I]
time 1363ms: Process J switching out of CPU; will block on I/O until time 1366ms
time 1366ms: Process J (tau 69ms) completed I/O; added to ready queue[Q H A E D J G C L B]
time 1367ms: Process I started using the CPU for 74ms burst [Q J G C L B E D H A]
time 1402ms: Process F (tau 39ms) completed I/O; added to ready queue[Q A E D J F L B C H G]
time 1441ms: Process I completed a CPU Burst; 61 bursts to go [Q L B H G C A E F D J]
time 1441ms: Recalculate tau = 110ms for Process I [Q L B H G C A E F D J]
time 1441ms: Process I switching out of CPU; will block on I/O until time 1447ms
time 1445ms: Process L started using the CPU for 117ms burst [Q F C H B G D J A E]
time 1447ms: Process I (tau 110ms) completed I/O; added to ready queue[Q H B F C I G D A E J]
time 1562ms: Process L terminated [Q H B F C I G D A E J]
time 1566ms: Process G started using the CPU for 82ms burst [Q C J A D E I F H B]
time 1648ms: Process G completed a CPU Burst; 73 bursts to go [Q E I F H B A D C J]
time 1648ms: Recalculate tau = 109ms for Process G [Q E I F H B A D C J]
time 1648ms: Process G switching out of CPU; will block on I/O until time 1728ms
time 1652ms: Process J started using the CPU for 137ms burst [Q E I H F B A C D]
time 1728ms: Process G (tau 109ms) completed I/O; added to ready queue[Q I E F H G A B C D]
time 1789ms: Process J completed a CPU Burst; 18 bursts to go [Q H G E F C D A B I]
time 1789ms: Recalculate tau = 103ms for Process J [Q H G E F C D A B I]
time 1789ms: Process J switching out of CPU; will block on I/O until time 1810ms
time 1793ms: Process I started using the CPU for 42ms burst [Q H G F E C D B A]
time 1810ms: Process J (tau 103ms) completed I/O; added to ready queue[Q C D B A J F E H G]
time 1835ms: Process I completed a CPU Burst; 60 bursts to go [Q A J D B H G F E C]
time 1835ms: Recalculate tau = 76ms for Process I [Q A J D B H G F E C]
time 1835ms: Process I switching out of CPU; will block on I/O until time 1906ms
time 1839ms: Process C started using the CPU for 148ms burst [Q A J B D H G E F]
time 1906ms: Process I (tau 76ms) completed I/O; added to ready queue[Q E F G H I J A B D]
time 1987ms: Process C completed a CPU Burst; 80 bursts to go [Q E F G H I J A B D]
time 1987ms: Recalculate tau = 119ms for Process C [Q E F G H I J A B D]
time 1987ms: Process C switching out of CPU; will block on I/O until time 1991ms
time 1991ms: Process D started using the CPU for 22ms burst [Q E F H G C I J A B]
time 1991ms: Process C (tau 119ms) completed I/O; added to ready queue[Q E F H G C I J A B]
time 2013ms: Process D completed a CPU Burst; 35 bursts to go [Q I G E B H A C F J]
time 2013ms: Recalculate tau = 61ms for Process D [Q I G E B H A C F J]
time 2013ms: Process D switching out of CPU; will block on I/O until time 2030ms
time 2017ms: Process J started using the CPU for 189ms burst [Q I G B E H A F C]
time 2030ms: Process D (tau 61ms) completed I/O; added to ready queue[Q A H C F D E B G I]
time 2206ms: Process J completed a CPU Burst; 17 bursts to go [Q C G D H B A I E F]
time 2206ms: Recalculate tau = 146ms for Process J [Q C G D H B A I E F]
time 2206ms: Process J switching out of CPU; will block on I/O until time 2371ms
time 2210ms: Process F started using the CPU for 1ms burst [Q C G H D B A E I]
time 2211ms: Process F completed a CPU Burst; 36 bursts to go [Q B A E I H D G C]
time 2211ms: Recalculate tau = 20ms for Process F [Q B A E I H D G C]
time 2211ms: Process F switching out of CPU; will block on I/O until time 2269ms
time 2215ms: Process E started using the CPU for 52ms burst [Q I A B G C D H]
time 2267ms: Process E completed a CPU Burst; 23 bursts to go [Q I A B G C D H]
time 2267ms: Recalculate tau = 57ms for Process E [Q I A B G C D H]
time 2267ms: Process E switching out of CPU; will block on I/O until time 2365ms
time 2269ms: Process F (tau 20ms) completed I/O; added to ready queue[Q C D H F B G A I]
time 2271ms: Process C started using the CPU for 9ms burst [Q D H F B G A I]
time 2280ms: Process C completed a CPU Burst; 79 bursts to go [Q D H F B G A I]
time 2280ms: Recalculate tau = 64ms for Process C [Q D H F B G A I]
time 2280ms: Process C switching out of CPU; will block on I/O until time 2320ms
time 2284ms: Process D started using the CPU for 52ms burst [Q H F B G A I]
time 2320ms: Process C (tau 64ms) completed I/O; added to ready queue[Q H F B G A I C]
time 2336ms: Process D completed a CPU Burst; 34 bursts to go [Q H F B G A I C]
time 2336ms: Recalculate tau = 57ms for Process D [Q H F B G A I C]
time 2336ms: Process D switching out of CPU; will block on I/O until time 2347ms
time 2340ms: Process H started using the CPU for 100ms burst [Q F B G A I C]
time 2347ms: Process D (tau 57ms) completed I/O; added to ready queue[Q F B G A I C D]
time 2365ms: Process E (tau 57ms) completed I/O; added to ready queue[Q I C D E G A B F]
time 2371ms: Process J (tau 146ms) completed I/O; added to ready queue[Q E D I C J F B A G]
time 2440ms: Process H completed a CPU Burst; 80 bursts to go [Q B E G F C J D I A]
time 2440ms: Recalculate tau = 78ms for Process H [Q B E G F C J D I A]
time 2440ms: Process H switching out of CPU; will block on I/O until time 2507ms
time 2444ms: Process A started using the CPU for 47ms burst [Q B E F G C J I D]
time 2491ms: Process A completed a CPU Burst; 12 bursts to go [Q D I C J B E F G]
time 2491ms: Recalculate tau = 51ms for Process A [Q D I C J B E F G]
time 2491ms: Process A switching out of CPU; will block on I/O until time 2495ms
time 2495ms: Process A (tau 51ms) completed I/O; added to ready queue[Q G E B A D F I J]
time 2495ms: Process C started using the CPU for 4ms burst [Q G E B A D F I J]
time 2499ms: Process C completed a CPU Burst; 78 bursts to go [Q E G A B F D J I]
time 2499ms: Recalculate tau = 34ms for Process C [Q E G A B F D J I]
time 2499ms: Process C switching out of CPU; will block on I/O until time 2549ms
time 2503ms: Process A started using the CPU for 137ms burst [Q B G E J I D F]
time 2507ms: Process H (tau 78ms) completed I/O; added to ready queue[Q I D F H E J G B]
time 2549ms: Process C (tau 34ms) completed I/O; added to ready queue[Q F H D I C G B E J]
time 2640ms: Process A completed a CPU Burst; 11 bursts to go [Q C G B E J D I F H]
time 2640ms: Recalculate tau = 94ms for Process A [Q C G B E J D I F H]
time 2640ms: Process A switching out of CPU; will block on I/O until time 2666ms
time 2644ms: Process H started using the CPU for 32ms burst [Q C G E B J D F I]
time 2666ms: Process A (tau 94ms) completed I/O; added to ready queue[Q B E C G A I F D J]
time 2676ms: Process H completed a CPU Burst; 79 bursts to go [Q A I F D J C G B E]
time 2676ms: Recalculate tau = 55ms for Process H [Q A I F D J C G B E]
time 2676ms: Process H switching out of CPU; will block on I/O until time 2736ms
time 2680ms: Process E started using the CPU for 199ms burst [Q A I D F J C B G]
time 2736ms: Process H (tau 55ms) completed I/O; added to ready queue[Q A I D F H J C G B]
time 2879ms: Process E completed a CPU Burst; 22 bursts to go [Q G B J C A I D F H]
time 2879ms: Recalculate tau = 128ms for Process E [Q G B J C A I D F H]
time 2879ms: Process E switching out of CPU; will block on I/O until time 2891ms
time 2883ms: Process H started using the CPU for 174ms burst [Q G B C J A I F D]
time 2891ms: Process E (tau 128ms) completed I/O; added to ready queue[Q G B C J E A I D F]
time 3057ms: Process H completed a CPU Burst; 78 bursts to go [Q A J G F C D E B I]
time 3057ms: Recalculate tau = 115ms for Process H [Q A J G F C D E B I]
time 3057ms: Process H switching out of CPU; will block on I/O until time 3154ms
time 3061ms: Process I started using the CPU for 95ms burst [Q A J F G C D B E]
time 3154ms: Process H (tau 115ms) completed I/O; added to ready queue[Q D C E B H G F J A]
time 3156ms: Process I completed a CPU Burst; 59 bursts to go [Q A E B D C F J H G]
time 3156ms: Recalculate tau = 86ms for Process I [Q A E B D C F J H G]
time 3156ms: Process I switching out of CPU; will block on I/O until time 3183ms
time 3160ms: Process G started using the CPU for 6ms burst [Q A E D B C F H J]
time 3166ms: Process G completed a CPU Burst; 72 bursts to go [Q B D A E J H C F]
time 3166ms: Recalculate tau = 58ms for Process G [Q B D A E J H C F]
time 3166ms: Process G switching out of CPU; will block on I/O until time 3184ms
time 3170ms: Process A started using the CPU for 64ms burst [Q E D B C F H J]
time 3183ms: Process I (tau 86ms) completed I/O; added to ready queue[Q F H J I B C D E]
time 3184ms: Process G (tau 58ms) completed I/O; added to ready queue[Q B C D E G J I F H]
time 3234ms: Process A completed a CPU Burst; 10 bursts to go [Q D F G C I B H J E]
time 3234ms: Recalculate tau = 79ms for Process A [Q D F G C I B H J E]
time 3234ms: Process A switching out of CPU; will block on I/O until time 3251ms
time 3238ms: Process E started using the CPU for 35ms burst [Q D F C G I B J H]
time 3251ms: Process A (tau 79ms) completed I/O; added to ready queue[Q B I H J A G C F D]
time 3273ms: Process E completed a CPU Burst; 21 bursts to go [Q G J B D H F A I C]
time 3273ms: Recalculate tau = 82ms for Process E [Q G J B D H F A I C]
time 3273ms: Process E switching out of CPU; will block on I/O until time 3346ms
time 3277ms: Process C started using the CPU for 149ms burst [Q G J D B H F I A]
time 3346ms: Process E (tau 82ms) completed I/O; added to ready queue[Q F H A I E B D J G]
time 3426ms: Process C completed a CPU Burst; 77 bursts to go [Q J G B D F H A I E]
time 3426ms: Recalculate tau = 92ms for Process C [Q J G B D F H A I E]
time 3426ms: Process C switching out of CPU; will block on I/O until time 3509ms
time 3430ms: Process E started using the CPU for 44ms burst [Q J G D B F H I A]
time 3474ms: Process E completed a CPU Burst; 20 bursts to go [Q G J B D H F A I]
time 3474ms: Recalculate tau = 63ms for Process E [Q G J B D H F A I]
time 3474ms: Process E switching out of CPU; will block on I/O until time 3500ms
time 3478ms: Process B started using the CPU for 198ms burst [Q D J G A I F H]
time 3500ms: Process E (tau 63ms) completed I/O; added to ready queue[Q I F H E G A J D]
time 3509ms: Process C (tau 92ms) completed I/O; added to ready queue[Q G A J D C H E I F]
time 3676ms: Process B completed a CPU Burst; 19 bursts to go [Q J I C A E G F H D]
time 3676ms: Recalculate tau = 151ms for Process B [Q J I C A E G F H D]
time 3676ms: Process B switching out of CPU; will block on I/O until time 3791ms
time 3680ms: Process D started using the CPU for 90ms burst [Q J I A C E G H F]
time 3770ms: Process D completed a CPU Burst; 33 bursts to go [Q A C I J H F G E]
time 3770ms: Recalculate tau = 74ms for Process D [Q A C I J H F G E]
time 3770ms: Process D switching out of CPU; will block on I/O until time 3776ms
time 3774ms: Process I started using the CPU for 119ms burst [Q J C A G E F H]
time 3776ms: Process D (tau 74ms) completed I/O; added to ready queue[Q E F H D A G C J]
time 3791ms: Process B (tau 151ms) completed I/O; added to ready queue[Q J C A G B E F D H]
time 3893ms: Process I completed a CPU Burst; 58 bursts to go [Q C F D B E G J H A]
time 3893ms: Recalculate tau = 103ms for Process I [Q C F D B E G J H A]
time 3893ms: Process I switching out of CPU; will block on I/O until time 3897ms
time 3897ms: Process A started using the CPU for 68ms burst [Q C F B D I E G J H]
time 3897ms: Process I (tau 103ms) completed I/O; added to ready queue[Q C F B D I E G J H]
time 3965ms: Process A completed a CPU Burst; 9 bursts to go [Q B J I F G C H E D]
time 3965ms: Recalculate tau = 74ms for Process A [Q B J I F G C H E D]
time 3965ms: Process A switching out of CPU; will block on I/O until time 4031ms
time 3969ms: Process D started using the CPU for 55ms burst [Q B J F I G C E H]
time 4024ms: Process D completed a CPU Burst; 32 bursts to go [Q H E G C B J F I]
time 4024ms: Recalculate tau = 65ms for Process D [Q H E G C B J F I]
time 4024ms: Process D switching out of CPU; will block on I/O until time 4056ms
time 4028ms: Process G started using the CPU for 55ms burst [Q C E H F I J B]
time 4031ms: Process A (tau 74ms) completed I/O; added to ready queue[Q I J B A H F E C]
time 4056ms: Process D (tau 65ms) completed I/O; added to ready queue[Q H F E C D B A I J]
time 4083ms: Process G completed a CPU Burst; 71 bursts to go [Q H F E C D B A I J]
time 4083ms: Recalculate tau = 57ms for Process G [Q H F E C D B A I J]
time 4083ms: Process G switching out of CPU; will block on I/O until time 4227ms
time 4087ms: Process J started using the CPU for 67ms burst [Q H F C E D B I A]
time 4154ms: Process J completed a CPU Burst; 16 bursts to go [Q I A B D F H E C]
time 4154ms: Recalculate tau = 107ms for Process J [Q I A B D F H E C]
time 4154ms: Process J switching out of CPU; will block on I/O until time 4198ms
time 4158ms: Process B started using the CPU for 162ms burst [Q D A I E C H F]
time 4198ms: Process J (tau 107ms) completed I/O; added to ready queue[Q C H F J I E A D]
time 4227ms: Process G (tau 57ms) completed I/O; added to ready queue[Q E I D A G J F H C]
time 4320ms: Process B completed a CPU Burst; 18 bursts to go [Q I F H G J A E C D]
time 4320ms: Recalculate tau = 157ms for Process B [Q I F H G J A E C D]
time 4320ms: Process B switching out of CPU; will block on I/O until time 4372ms
time 4324ms: Process D started using the CPU for 46ms burst [Q I F G H J A C E]
time 4370ms: Process D completed a CPU Burst; 31 bursts to go [Q H G I F E C J A]
time 4370ms: Recalculate tau = 56ms for Process D [Q H G I F E C J A]
time 4370ms: Process D switching out of CPU; will block on I/O until time 4555ms
time 4372ms: Process B (tau 157ms) completed I/O; added to ready queue[Q I F G H B J A E C]
time 4374ms: Process I started using the CPU for 37ms burst [Q H B G F E C A J]
time 4411ms: Process I completed a CPU Burst; 57 bursts to go [Q C E J A F G H B]
time 4411ms: Recalculate tau = 70ms for Process I [Q C E J A F G H B]
time 4411ms: Process I switching out of CPU; will block on I/O until time 4577ms
time 4415ms: Process J started using the CPU for 35ms burst [Q A E C H B G F]
time 4450ms: Process J completed a CPU Burst; 15 bursts to go [Q A E C H B G F]
time 4450ms: Recalculate tau = 71ms for Process J [Q A E C H B G F]
time 4450ms: Process J switching out of CPU; will block on I/O until time 4556ms
time 4454ms: Process A started using the CPU for 113ms burst [Q E C H B G F]
time 4555ms: Process D (tau 56ms) completed I/O; added to ready queue[Q E C H B G F D]
time 4556ms: Process J (tau 71ms) completed I/O; added to ready queue[Q G F D J H B C E]
time 4567ms: Process A completed a CPU Burst; 8 bursts to go [Q C E B H F G J D]
time 4567ms: Recalculate tau = 94ms for Process A [Q C E B H F G J D]
time 4567ms: Process A switching out of CPU; will block on I/O until time 4585ms
time 4571ms: Process B started using the CPU for 46ms burst [Q H E C J D G F]
time 4577ms: Process I (tau 70ms) completed I/O; added to ready queue[Q D G F I C J E H]
time 4585ms: Process A (tau 94ms) completed I/O; added to ready queue[Q D G F I A C J H E]
time 4617ms: Process B completed a CPU Burst; 17 bursts to go [Q F H A G J D E C I]
time 4617ms: Recalculate tau = 102ms for Process B [Q F H A G J D E C I]
time 4617ms: Process B switching out of CPU; will block on I/O until time 4701ms
time 4621ms: Process I started using the CPU for 50ms burst [Q F H G A J D C E]
time 4671ms: Process I completed a CPU Burst; 56 bursts to go [Q G A H F C E D J]
time 4671ms: Recalculate tau = 60ms for Process I [Q G A H F C E D J]
time 4671ms: Process I switching out of CPU; will block on I/O until time 4784ms
time 4675ms: Process H started using the CPU for 142ms burst [Q F A G D J E C]
time 4701ms: Process B (tau 102ms) completed I/O; added to ready queue[Q J E C B G D A F]
time 4784ms: Process I (tau 60ms) completed I/O; added to ready queue[Q A F D G I E J C B]
time 4817ms: Process H completed a CPU Burst; 77 bursts to go [Q J A B E G I F D C]
time 4817ms: Recalculate tau = 129ms for Process H [Q J A B E G I F D C]
time 4817ms: Process H switching out of CPU; will block on I/O until time 4897ms
time 4821ms: Process C started using the CPU for 52ms burst [Q J A E B G I D F]
time 4873ms: Process C completed a CPU Burst; 76 bursts to go [Q A J B E I G F D]
time 4873ms: Recalculate tau = 72ms for Process C [Q A J B E I G F D]
time 4873ms: Process C switching out of CPU; will block on I/O until time 4878ms
time 4877ms: Process B started using the CPU for 16ms burst [Q E J A F D G I]
time 4878ms: Process C (tau 72ms) completed I/O; added to ready queue[Q D G I C A F J E]
time 4893ms: Process B completed a CPU Burst; 16 bursts to go [Q E J A F D G I C]
time 4893ms: Recalculate tau = 59ms for Process B [Q E J A F D G I C]
time 4893ms: Process B switching out of CPU; will block on I/O until time 4902ms
time 4897ms: Process A started using the CPU for 11ms burst [Q C G D H E I J F]
time 4897ms: Process H (tau 129ms) completed I/O; added to ready queue[Q C G D H E I J F]
time 4902ms: Process B (tau 59ms) completed I/O; added to ready queue[Q I E F J B H D G C]
time 4908ms: Process A completed a CPU Burst; 7 bursts to go [Q D I C H J B E F G]
time 4908ms: Recalculate tau = 53ms for Process A [Q D I C H J B E F G]
time 4908ms: Process A switching out of CPU; will block on I/O until time 5072ms
time 4912ms: Process G started using the CPU for 97ms burst [Q D I H C J B F E]
time 5009ms: Process G completed a CPU Burst; 70 bursts to go [Q J B F E H C I D]
time 5009ms: Recalculate tau = 77ms for Process G [Q J B F E H C I D]
time 5009ms: Process G switching out of CPU; will block on I/O until time 5073ms
time 5013ms: Process F started using the CPU for 25ms burst [Q E B J I D C H]
time 5038ms: Process F completed a CPU Burst; 35 bursts to go [Q E B J I D C H]
time 5038ms: Recalculate tau = 23ms for Process F [Q E B J I D C H]
time 5038ms: Process F switching out of CPU; will block on I/O until time 5043ms
time 5042ms: Process E started using the CPU for 27ms burst [Q B J I D C H]
time 5043ms: Process F (tau 23ms) completed I/O; added to ready queue[Q B J I D C H F]
time 5069ms: Process E completed a CPU Burst; 19 bursts to go [Q B J I D C H F]
time 5069ms: Recalculate tau = 45ms for Process E [Q B J I D C H F]
time 5069ms: Process E switching out of CPU; will block on I/O until time 5194ms
time 5072ms: Process A (tau 53ms) completed I/O; added to ready queue[Q J I D C H F A]
time 5073ms: Process B started using the CPU for 30ms burst [Q H F A G D C I J]
time 5073ms: Process G (tau 77ms) completed I/O; added to ready queue[Q H F A G D C I J]
time 5103ms: Process B completed a CPU Burst; 15 bursts to go [Q G A H F J I D C]
time 5103ms: Recalculate tau = 45ms for Process B [Q G A H F J I D C]
time 5103ms: Process B switching out of CPU; will block on I/O until time 5157ms
time 5107ms: Process H started using the CPU for 77ms burst [Q F A G D C I J]
time 5157ms: Process B (tau 45ms) completed I/O; added to ready queue[Q C I J B G D A F]
time 5184ms: Process H completed a CPU Burst; 76 bursts to go [Q A F D G I C B J]
time 5184ms: Recalculate tau = 103ms for Process H [Q A F D G I C B J]
time 5184ms: Process H switching out of CPU; will block on I/O until time 5217ms
time 5188ms: Process D started using the CPU for 41ms burst [Q G F A B J C I]
time 5194ms: Process E (tau 45ms) completed I/O; added to ready queue[Q J C I E A B F G]
time 5217ms: Process H (tau 103ms) completed I/O; added to ready queue[Q G F A B H J C E I]
time 5229ms: Process D completed a CPU Burst; 30 bursts to go [Q F C E H J B G I A]
time 5229ms: Recalculate tau = 49ms for Process D [Q F C E H J B G I A]
time 5229ms: Process D switching out of CPU; will block on I/O until time 5252ms
time 5233ms: Process A started using the CPU for 24ms burst [Q F C H E J B I G]
time 5252ms: Process D (tau 49ms) completed I/O; added to ready queue[Q I G B J D C F H E]
time 5257ms: Process A completed a CPU Burst; 6 bursts to go [Q B H D G F I E C J]
time 5257ms: Recalculate tau = 39ms for Process A [Q B H D G F I E C J]
time 5257ms: Process A switching out of CPU; will block on I/O until time 5376ms
time 5261ms: Process J started using the CPU for 2ms burst [Q B H G D F I C E]
time 5263ms: Process J completed a CPU Burst; 14 bursts to go [Q G D H B C E I F]
time 5263ms: Recalculate tau = 37ms for Process J [Q G D H B C E I F]
time 5263ms: Process J switching out of CPU; will block on I/O until time 5395ms
time 5267ms: Process H started using the CPU for 109ms burst [Q B D G I F E C]
time 5376ms: Process A (tau 39ms) completed I/O; added to ready queue[Q F E C A G I D B]
time 5376ms: Process H completed a CPU Burst; 75 bursts to go [Q F E C A G I D B]
time 5376ms: Recalculate tau = 106ms for Process H [Q F E C A G I D B]
time 5376ms: Process H switching out of CPU; will block on I/O until time 5475ms
time 5380ms: Process C started using the CPU for 23ms burst [Q A E F D B I G]
time 5395ms: Process J (tau 37ms) completed I/O; added to ready queue[Q B I G J F D E A]
time 5403ms: Process C completed a CPU Burst; 75 bursts to go [Q B I G J F D E A]
time 5403ms: Recalculate tau = 48ms for Process C [Q B I G J F D E A]
time 5403ms: Process C switching out of CPU; will block on I/O until time 5599ms
time 5407ms: Process G started using the CPU for 25ms burst [Q J I B E A D F]
time 5432ms: Process G completed a CPU Burst; 69 bursts to go [Q J I B E A D F]
time 5432ms: Recalculate tau = 51ms for Process G [Q J I B E A D F]
time 5432ms: Process G switching out of CPU; will block on I/O until time 5516ms
time 5436ms: Process J started using the CPU for 158ms burst [Q I B E A D F]
time 5475ms: Process H (tau 106ms) completed I/O; added to ready queue[Q I B E A D F H]
time 5516ms: Process G (tau 51ms) completed I/O; added to ready queue[Q D F H G E A B I]
time 5594ms: Process J completed a CPU Burst; 13 bursts to go [Q G H D F I B E A]
time 5594ms: Recalculate tau = 98ms for Process J [Q G H D F I B E A]
time 5594ms: Process J switching out of CPU; will block on I/O until time 5787ms
time 5598ms: Process D started using the CPU for 117ms burst [Q F H G E A B I]
time 5599ms: Process C (tau 48ms) completed I/O; added to ready queue[Q A B I C G E H F]
time 5715ms: Process D completed a CPU Burst; 29 bursts to go [Q B A C I E G F H]
time 5715ms: Recalculate tau = 83ms for Process D [Q B A C I E G F H]
time 5715ms: Process D switching out of CPU; will block on I/O until time 5818ms
time 5719ms: Process C started using the CPU for 76ms burst [Q I A B F H G E]
time 5787ms: Process J (tau 98ms) completed I/O; added to ready queue[Q H G E J B F A I]
time 5795ms: Process C completed a CPU Burst; 74 bursts to go [Q H G E J B F A I]
time 5795ms: Recalculate tau = 62ms for Process C [Q H G E J B F A I]
time 5795ms: Process C switching out of CPU; will block on I/O until time 5870ms
time 5799ms: Process E started using the CPU for 171ms burst [Q J G H A I F B]
time 5818ms: Process D (tau 83ms) completed I/O; added to ready queue[Q I F B D H A G J]
time 5870ms: Process C (tau 62ms) completed I/O; added to ready queue[Q F I D B C A H G J]
time 5970ms: Process E completed a CPU Burst; 18 bursts to go [Q C A H G J D B F I]
time 5970ms: Recalculate tau = 108ms for Process E [Q C A H G J D B F I]
time 5970ms: Process E switching out of CPU; will block on I/O until time 6001ms
time 5974ms: Process I started using the CPU for 17ms burst [Q C A G H J D F B]
time 5991ms: Process I completed a CPU Burst; 55 bursts to go [Q J D F B G H A C]
time 5991ms: Recalculate tau = 39ms for Process I [Q J D F B G H A C]
time 5991ms: Process I switching out of CPU; will block on I/O until time 6069ms
time 5995ms: Process F started using the CPU for 47ms burst [Q B D J A C H G]
time 6001ms: Process E (tau 108ms) completed I/O; added to ready queue[Q C H G E J A D B]
time 6042ms: Process F completed a CPU Burst; 34 bursts to go [Q J A D B G E H C]
time 6042ms: Recalculate tau = 35ms for Process F [Q J A D B G E H C]
time 6042ms: Process F switching out of CPU; will block on I/O until time 6233ms
time 6046ms: Process D started using the CPU for 90ms burst [Q B A J H C E G]
time 6069ms: Process I (tau 39ms) completed I/O; added to ready queue[Q C E G I J H A B]
time 6136ms: Process D completed a CPU Burst; 28 bursts to go [Q A B H J E C I G]
time 6136ms: Recalculate tau = 87ms for Process D [Q A B H J E C I G]
time 6136ms: Process D switching out of CPU; will block on I/O until time 6140ms
time 6140ms: Process D (tau 87ms) completed I/O; added to ready queue[Q G C E D A I B J]
time 6140ms: Process H started using the CPU for 18ms burst [Q G C E D A I B J]
time 6158ms: Process H completed a CPU Burst; 74 bursts to go [Q E D C G B J I A]
time 6158ms: Recalculate tau = 62ms for Process H [Q E D C G B J I A]
time 6158ms: Process H switching out of CPU; will block on I/O until time 6263ms
time 6162ms: Process C started using the CPU for 50ms burst [Q G D E I A J B]
time 6212ms: Process C completed a CPU Burst; 73 bursts to go [Q G D E I A J B]
time 6212ms: Recalculate tau = 56ms for Process C [Q G D E I A J B]
time 6212ms: Process C switching out of CPU; will block on I/O until time 6226ms
time 6216ms: Process G started using the CPU for 37ms burst [Q D E I A J B]
time 6226ms: Process C (tau 56ms) completed I/O; added to ready queue[Q D E I A J B C]
time 6233ms: Process F (tau 35ms) completed I/O; added to ready queue[Q J B C F I A E D]
time 6253ms: Process G completed a CPU Burst; 68 bursts to go [Q B J F C A I D E]
time 6253ms: Recalculate tau = 44ms for Process G [Q B J F C A I D E]
time 6253ms: Process G switching out of CPU; will block on I/O until time 6258ms
time 6257ms: Process F started using the CPU for 84ms burst [Q C J B D E I A]
time 6258ms: Process G (tau 44ms) completed I/O; added to ready queue[Q E I A G B D J C]
time 6263ms: Process H (tau 62ms) completed I/O; added to ready queue[Q D B C J H G A I E]
time 6341ms: Process F completed a CPU Burst; 33 bursts to go [Q A D E G J H B C I]
time 6341ms: Recalculate tau = 60ms for Process F [Q A D E G J H B C I]
time 6341ms: Process F switching out of CPU; will block on I/O until time 6438ms
time 6345ms: Process I started using the CPU for 22ms burst [Q A D G E J H C B]
time 6367ms: Process I completed a CPU Burst; 54 bursts to go [Q E G A D B C J H]
time 6367ms: Recalculate tau = 31ms for Process I [Q E G A D B C J H]
time 6367ms: Process I switching out of CPU; will block on I/O until time 6386ms
time 6371ms: Process A started using the CPU for 76ms burst [Q D G E J H C B]
time 6386ms: Process I (tau 31ms) completed I/O; added to ready queue[Q H C B I E J G D]
time 6438ms: Process F (tau 60ms) completed I/O; added to ready queue[Q C H I B F J E G D]
time 6447ms: Process A completed a CPU Burst; 5 bursts to go [Q C H I B F J E G D]
time 6447ms: Recalculate tau = 58ms for Process A [Q C H I B F J E G D]
time 6447ms: Process A switching out of CPU; will block on I/O until time 6477ms
time 6451ms: Process D started using the CPU for 170ms burst [Q C H B I F J G E]
time 6477ms: Process A (tau 58ms) completed I/O; added to ready queue[Q B I H C A G E F J]
time 6621ms: Process D completed a CPU Burst; 27 bursts to go [Q B I H C A G E F J]
time 6621ms: Recalculate tau = 129ms for Process D [Q B I H C A G E F J]
time 6621ms: Process D switching out of CPU; will block on I/O until time 6681ms
time 6625ms: Process J started using the CPU for 52ms burst [Q B I C H A G F E]
time 6677ms: Process J completed a CPU Burst; 12 bursts to go [Q I B H C G A E F]
time 6677ms: Recalculate tau = 75ms for Process J [Q I B H C G A E F]
time 6677ms: Process J switching out of CPU; will block on I/O until time 6681ms
time 6681ms: Process D (tau 129ms) completed I/O; added to ready queue[Q F A G D J I E C B]
time 6681ms: Process H started using the CPU for 87ms burst [Q F A G D J I E C B]
time 6681ms: Process J (tau 75ms) completed I/O; added to ready queue[Q F A G D J I E C B]
time 6768ms: Process H completed a CPU Burst; 73 bursts to go [Q E F B I D J A G C]
time 6768ms: Recalculate tau = 75ms for Process H [Q E F B I D J A G C]
time 6768ms: Process H switching out of CPU; will block on I/O until time 6814ms
time 6772ms: Process C started using the CPU for 24ms burst [Q E F I B D J G A]
time 6796ms: Process C completed a CPU Burst; 72 bursts to go [Q E F I B D J G A]
time 6796ms: Recalculate tau = 40ms for Process C [Q E F I B D J G A]
time 6796ms: Process C switching out of CPU; will block on I/O until time 6823ms
time 6800ms: Process I started using the CPU for 93ms burst [Q B F E G A J D]
time 6814ms: Process H (tau 75ms) completed I/O; added to ready queue[Q A J D H E G F B]
time 6823ms: Process C (tau 40ms) completed I/O; added to ready queue[Q E G F B C D H A J]
time 6893ms: Process I completed a CPU Burst; 53 bursts to go [Q B C G F A J D H E]
time 6893ms: Recalculate tau = 62ms for Process I [Q B C G F A J D H E]
time 6893ms: Process I switching out of CPU; will block on I/O until time 6937ms
time 6897ms: Process E started using the CPU for 3ms burst [Q B C F G A J H D]
time 6900ms: Process E completed a CPU Burst; 17 bursts to go [Q H D J A C B G F]
time 6900ms: Recalculate tau = 56ms for Process E [Q H D J A C B G F]
time 6900ms: Process E switching out of CPU; will block on I/O until time 7032ms
time 6904ms: Process J started using the CPU for 55ms burst [Q A D H G F B C]
time 6937ms: Process I (tau 62ms) completed I/O; added to ready queue[Q F B C I H G D A]
time 6959ms: Process J completed a CPU Burst; 11 bursts to go [Q I C F B A D H G]
time 6959ms: Recalculate tau = 65ms for Process J [Q I C F B A D H G]
time 6959ms: Process J switching out of CPU; will block on I/O until time 6976ms
time 6963ms: Process F started using the CPU for 26ms burst [Q B C I H G D A]
time 6976ms: Process J (tau 65ms) completed I/O; added to ready queue[Q G D A J I H C B]
time 6989ms: Process F completed a CPU Burst; 32 bursts to go [Q H I B C J A G D]
time 6989ms: Recalculate tau = 43ms for Process F [Q H I B C J A G D]
time 6989ms: Process F switching out of CPU; will block on I/O until time 7159ms
time 6993ms: Process B started using the CPU for 12ms burst [Q C I H G D A J]
time 7005ms: Process B completed a CPU Burst; 14 bursts to go [Q C I H G D A J]
time 7005ms: Recalculate tau = 29ms for Process B [Q C I H G D A J]
time 7005ms: Process B switching out of CPU; will block on I/O until time 7084ms
time 7009ms: Process C started using the CPU for 1ms burst [Q I H G D A J]
time 7010ms: Process C completed a CPU Burst; 71 bursts to go [Q I H G D A J]
time 7010ms: Recalculate tau = 21ms for Process C [Q I H G D A J]
time 7010ms: Process C switching out of CPU; will block on I/O until time 7147ms
time 7014ms: Process I started using the CPU for 79ms burst [Q H G D A J]
time 7032ms: Process E (tau 56ms) completed I/O; added to ready queue[Q H G D A J E]
time 7084ms: Process B (tau 29ms) completed I/O; added to ready queue[Q H G D A J E B]
time 7093ms: Process I completed a CPU Burst; 52 bursts to go [Q H G D A J E B]
time 7093ms: Recalculate tau = 71ms for Process I [Q H G D A J E B]
time 7093ms: Process I switching out of CPU; will block on I/O until time 7209ms
time 7097ms: Process H started using the CPU for 199ms burst [Q G D A J E B]
time 7147ms: Process C (tau 21ms) completed I/O; added to ready queue[Q G D A J E B C]
time 7159ms: Process F (tau 43ms) completed I/O; added to ready queue[Q E B C F A J D G]
time 7209ms: Process I (tau 71ms) completed I/O; added to ready queue[Q C F B E I D G A J]
time 7296ms: Process H completed a CPU Burst; 72 bursts to go [Q G C J D E I F B A]
time 7296ms: Recalculate tau = 137ms for Process H [Q G C J D E I F B A]
time 7296ms: Process H switching out of CPU; will block on I/O until time 7335ms
time 7300ms: Process A started using the CPU for 122ms burst [Q G C D J E I B F]
time 7335ms: Process H (tau 137ms) completed I/O; added to ready queue[Q B F I E H C G D J]
time 7422ms: Process A completed a CPU Burst; 4 bursts to go [Q G B J C E H F I D]
time 7422ms: Recalculate tau = 90ms for Process A [Q G B J C E H F I D]
time 7422ms: Process A switching out of CPU; will block on I/O until time 7457ms
time 7426ms: Process D started using the CPU for 154ms burst [Q G B C J E H I F]
time 7457ms: Process A (tau 90ms) completed I/O; added to ready queue[Q F I E H A G B J C]
time 7580ms: Process D completed a CPU Burst; 26 bursts to go [Q B F C G H A I E J]
time 7580ms: Recalculate tau = 142ms for Process D [Q B F C G H A I E J]
time 7580ms: Process D switching out of CPU; will block on I/O until time 7618ms
time 7584ms: Process J started using the CPU for 32ms burst [Q B F G C H A E I]
time 7616ms: Process J completed a CPU Burst; 10 bursts to go [Q B F G C H A E I]
time 7616ms: Recalculate tau = 49ms for Process J [Q B F G C H A E I]
time 7616ms: Process J switching out of CPU; will block on I/O until time 7710ms
time 7618ms: Process D (tau 142ms) completed I/O; added to ready queue[Q G C F B D E I H A]
time 7620ms: Process G started using the CPU for 10ms burst [Q B D F C H A I E]
time 7630ms: Process G completed a CPU Burst; 67 bursts to go [Q F C D B I E A H]
time 7630ms: Recalculate tau = 27ms for Process G [Q F C D B I E A H]
time 7630ms: Process G switching out of CPU; will block on I/O until time 7638ms
time 7634ms: Process D started using the CPU for 55ms burst [Q B C F A H E I]
time 7638ms: Process G (tau 27ms) completed I/O; added to ready queue[Q H E I G F A C B]
time 7689ms: Process D completed a CPU Burst; 25 bursts to go [Q C B A F E H G I]
time 7689ms: Recalculate tau = 99ms for Process D [Q C B A F E H G I]
time 7689ms: Process D switching out of CPU; will block on I/O until time 7816ms
time 7693ms: Process A started using the CPU for 9ms burst [Q F B C G I H E]
time 7702ms: Process A completed a CPU Burst; 3 bursts to go [Q F B C G I H E]
time 7702ms: Recalculate tau = 50ms for Process A [Q F B C G I H E]
time 7702ms: Process A switching out of CPU; will block on I/O until time 7772ms
time 7706ms: Process F started using the CPU for 91ms burst [Q B C G I H E]
time 7710ms: Process J (tau 49ms) completed I/O; added to ready queue[Q B C G I H E J]
time 7772ms: Process A (tau 50ms) completed I/O; added to ready queue[Q H E J A G I C B]
time 7797ms: Process F completed a CPU Burst; 31 bursts to go [Q G I C B J A E H]
time 7797ms: Recalculate tau = 67ms for Process F [Q G I C B J A E H]
time 7797ms: Process F switching out of CPU; will block on I/O until time 7834ms
time 7801ms: Process C started using the CPU for 61ms burst [Q B I G E H A J]
time 7816ms: Process D (tau 99ms) completed I/O; added to ready queue[Q H A J D G E I B]
time 7834ms: Process F (tau 67ms) completed I/O; added to ready queue[Q J D A H F I B G E]
time 7862ms: Process C completed a CPU Burst; 70 bursts to go [Q F I B G E A H J D]
time 7862ms: Recalculate tau = 41ms for Process C [Q F I B G E A H J D]
time 7862ms: Process C switching out of CPU; will block on I/O until time 8016ms
time 7866ms: Process D started using the CPU for 27ms burst [Q F I G B E A J H]
time 7893ms: Process D completed a CPU Burst; 24 bursts to go [Q J H A E I F B G]
time 7893ms: Recalculate tau = 63ms for Process D [Q J H A E I F B G]
time 7893ms: Process D switching out of CPU; will block on I/O until time 8017ms
time 7897ms: Process A started using the CPU for 62ms burst [Q E H J B G F I]
time 7959ms: Process A completed a CPU Burst; 2 bursts to go [Q E H J B G F I]
time 7959ms: Recalculate tau = 56ms for Process A [Q E H J B G F I]
time 7959ms: Process A switching out of CPU; will block on I/O until time 8038ms
time 7963ms: Process E started using the CPU for 107ms burst [Q H J B G F I]
time 8016ms: Process C (tau 41ms) completed I/O; added to ready queue[Q H J B G F I C]
time 8017ms: Process D (tau 63ms) completed I/O; added to ready queue[Q F I C D B G J H]
time 8038ms: Process A (tau 56ms) completed I/O; added to ready queue[Q G B H J A D C I F]
time 8070ms: Process E completed a CPU Burst; 16 bursts to go [Q H I A B C G F D J]
time 8070ms: Recalculate tau = 82ms for Process E [Q H I A B C G F D J]
time 8070ms: Process E switching out of CPU; will block on I/O until time 8089ms
time 8074ms: Process J started using the CPU for 101ms burst [Q H I B A C G D F]
time 8089ms: Process E (tau 82ms) completed I/O; added to ready queue[Q F D C G E H I A B]
time 8175ms: Process J completed a CPU Burst; 9 bursts to go [Q C A E D I F B H G]
time 8175ms: Recalculate tau = 75ms for Process J [Q C A E D I F B H G]
time 8175ms: Process J switching out of CPU; will block on I/O until time 8352ms
time 8179ms: Process G started using the CPU for 189ms burst [Q C A D E I F H B]
time 8352ms: Process J (tau 75ms) completed I/O; added to ready queue[Q F I B H J E D A C]
time 8368ms: Process G completed a CPU Burst; 66 bursts to go [Q H J I B A C E D F]
time 8368ms: Recalculate tau = 108ms for Process G [Q H J I B A C E D F]
time 8368ms: Process G switching out of CPU; will block on I/O until time 8418ms
time 8372ms: Process F started using the CPU for 166ms burst [Q H J B I A C D E]
time 8418ms: Process G (tau 108ms) completed I/O; added to ready queue[Q I B H J G E D C A]
time 8538ms: Process F completed a CPU Burst; 30 bursts to go [Q B D C G E J I A H]
time 8538ms: Recalculate tau = 117ms for Process F [Q B D C G E J I A H]
time 8538ms: Process F switching out of CPU; will block on I/O until time 8599ms
time 8542ms: Process H started using the CPU for 90ms burst [Q B D G C E J A I]
time 8599ms: Process F (tau 117ms) completed I/O; added to ready queue[Q E J A I F G C B D]
time 8632ms: Process H completed a CPU Burst; 71 bursts to go [Q C E D G I F J A B]
time 8632ms: Recalculate tau = 114ms for Process H [Q C E D G I F J A B]
time 8632ms: Process H switching out of CPU; will block on I/O until time 8635ms
time 8635ms: Process H (tau 114ms) completed I/O; added to ready queue[Q J A I F H C E D G]
time 8636ms: Process B started using the CPU for 138ms burst [Q H C E D G I F J A]
time 8774ms: Process B completed a CPU Burst; 13 bursts to go [Q C F J G I D H A E]
time 8774ms: Recalculate tau = 84ms for Process B [Q C F J G I D H A E]
time 8774ms: Process B switching out of CPU; will block on I/O until time 8858ms
time 8778ms: Process E started using the CPU for 111ms burst [Q C F G J I D A H]
time 8858ms: Process B (tau 84ms) completed I/O; added to ready queue[Q C F G J B I D H A]
time 8889ms: Process E completed a CPU Burst; 15 bursts to go [Q I J C A G H B F D]
time 8889ms: Recalculate tau = 97ms for Process E [Q I J C A G H B F D]
time 8889ms: Process E switching out of CPU; will block on I/O until time 8922ms
time 8893ms: Process D started using the CPU for 73ms burst [Q I J A C G H F B]
time 8922ms: Process E (tau 97ms) completed I/O; added to ready queue[Q H G B F E C A J I]
time 8966ms: Process D completed a CPU Burst; 23 bursts to go [Q J I C A H G B F E]
time 8966ms: Recalculate tau = 68ms for Process D [Q J I C A H G B F E]
time 8966ms: Process D switching out of CPU; will block on I/O until time 9023ms
time 8970ms: Process E started using the CPU for 11ms burst [Q J I A C H G F B]
time 8981ms: Process E completed a CPU Burst; 14 bursts to go [Q F B G H I J C A]
time 8981ms: Recalculate tau = 54ms for Process E [Q F B G H I J C A]
time 8981ms: Process E switching out of CPU; will block on I/O until time 9061ms
time 8985ms: Process G started using the CPU for 134ms burst [Q H B F C A J I]
time 9023ms: Process D (tau 68ms) completed I/O; added to ready queue[Q A J I D F C B H]
time 9061ms: Process E (tau 54ms) completed I/O; added to ready queue[Q D I A J E H B C F]
time 9119ms: Process G completed a CPU Burst; 65 bursts to go [Q H J D F A C E I B]
time 9119ms: Recalculate tau = 121ms for Process G [Q H J D F A C E I B]
time 9119ms: Process G switching out of CPU; will block on I/O until time 9154ms
time 9123ms: Process B started using the CPU for 67ms burst [Q H J F D A C I E]
time 9154ms: Process G (tau 121ms) completed I/O; added to ready queue[Q E I A C G H J D F]
time 9190ms: Process B completed a CPU Burst; 12 bursts to go [Q E I A C G H J D F]
time 9190ms: Recalculate tau = 76ms for Process B [Q E I A C G H J D F]
time 9190ms: Process B switching out of CPU; will block on I/O until time 9199ms
time 9194ms: Process F started using the CPU for 67ms burst [Q E I C A G H D J]
time 9199ms: Process B (tau 76ms) completed I/O; added to ready queue[Q H G J D B A C I E]
time 9261ms: Process F completed a CPU Burst; 29 bursts to go [Q I E A C H G J D B]
time 9261ms: Recalculate tau = 92ms for Process F [Q I E A C H G J D B]
time 9261ms: Process F switching out of CPU; will block on I/O until time 9454ms
time 9265ms: Process B started using the CPU for 120ms burst [Q I E C A H G D J]
time 9385ms: Process B completed a CPU Burst; 11 bursts to go [Q I E C A H G D J]
time 9385ms: Recalculate tau = 98ms for Process B [Q I E C A H G D J]
time 9385ms: Process B switching out of CPU; will block on I/O until time 9400ms
time 9389ms: Process C started using the CPU for 46ms burst [Q A E I D J G H]
time 9400ms: Process B (tau 98ms) completed I/O; added to ready queue[Q J G H B I D E A]
time 9435ms: Process C completed a CPU Burst; 69 bursts to go [Q E A D I G J B H]
time 9435ms: Recalculate tau = 44ms for Process C [Q E A D I G J B H]
time 9435ms: Process C switching out of CPU; will block on I/O until time 9481ms
time 9439ms: Process D started using the CPU for 66ms burst [Q I A E B H J G]
time 9454ms: Process F (tau 92ms) completed I/O; added to ready queue[Q H J G F E B A I]
time 9481ms: Process C (tau 44ms) completed I/O; added to ready queue[Q A I B E C J H G F]
time 9505ms: Process D completed a CPU Burst; 22 bursts to go [Q H A F J E C I B G]
time 9505ms: Recalculate tau = 67ms for Process D [Q H A F J E C I B G]
time 9505ms: Process D switching out of CPU; will block on I/O until time 9531ms
time 9509ms: Process G started using the CPU for 25ms burst [Q H A J F E C B I]
time 9531ms: Process D (tau 67ms) completed I/O; added to ready queue[Q F J H A D I B C E]
time 9534ms: Process G completed a CPU Burst; 64 bursts to go [Q J B C D I A F E H]
time 9534ms: Recalculate tau = 73ms for Process G [Q J B C D I A F E H]
time 9534ms: Process G switching out of CPU; will block on I/O until time 9617ms
time 9538ms: Process H started using the CPU for 2ms burst [Q J B D C I A E F]
time 9540ms: Process H completed a CPU Burst; 70 bursts to go [Q D C B J E F A I]
time 9540ms: Recalculate tau = 58ms for Process H [Q D C B J E F A I]
time 9540ms: Process H switching out of CPU; will block on I/O until time 9638ms
time 9544ms: Process B started using the CPU for 49ms burst [Q J C D A I F E]
time 9593ms: Process B completed a CPU Burst; 10 bursts to go [Q J C D A I F E]
time 9593ms: Recalculate tau = 74ms for Process B [Q J C D A I F E]
time 9593ms: Process B switching out of CPU; will block on I/O until time 9637ms
time 9597ms: Process J started using the CPU for 77ms burst [Q C D A I F E]
time 9617ms: Process G (tau 73ms) completed I/O; added to ready queue[Q C D A I F E G]
time 9637ms: Process B (tau 74ms) completed I/O; added to ready queue[Q F E G B A I D C]
time 9638ms: Process H (tau 58ms) completed I/O; added to ready queue[Q A I D C H G B F E]
time 9674ms: Process J completed a CPU Burst; 8 bursts to go [Q A I D C H G B F E]
time 9674ms: Recalculate tau = 76ms for Process J [Q A I D C H G B F E]
time 9674ms: Process J switching out of CPU; will block on I/O until time 9680ms
time 9678ms: Process E started using the CPU for 28ms burst [Q A I C D H G F B]
time 9680ms: Process J (tau 76ms) completed I/O; added to ready queue[Q C D I A J F B H G]
time 9706ms: Process E completed a CPU Burst; 13 bursts to go [Q H G F B C D I A J]
time 9706ms: Recalculate tau = 41ms for Process E [Q H G F B C D I A J]
time 9706ms: Process E switching out of CPU; will block on I/O until time 9714ms
time 9710ms: Process J started using the CPU for 18ms burst [Q H G B F C D A I]
time 9714ms: Process E (tau 41ms) completed I/O; added to ready queue[Q G H F B E D C A I]
time 9728ms: Process J completed a CPU Burst; 7 bursts to go [Q F A E H C G I D B]
time 9728ms: Recalculate tau = 47ms for Process J [Q F A E H C G I D B]
time 9728ms: Process J switching out of CPU; will block on I/O until time 9813ms
time 9732ms: Process B started using the CPU for 134ms burst [Q F A H E C G D I]
time 9813ms: Process J (tau 47ms) completed I/O; added to ready queue[Q C G D I J H E F A]
time 9866ms: Process B completed a CPU Burst; 9 bursts to go [Q F A H E C G D I J]
time 9866ms: Recalculate tau = 104ms for Process B [Q F A H E C G D I J]
time 9866ms: Process B switching out of CPU; will block on I/O until time 9900ms
time 9870ms: Process J started using the CPU for 9ms burst [Q F A E H C G I D]
time 9879ms: Process J completed a CPU Burst; 6 bursts to go [Q C G I D E H A F]
time 9879ms: Recalculate tau = 28ms for Process J [Q C G I D E H A F]
time 9879ms: Process J switching out of CPU; will block on I/O until time 9884ms
time 9883ms: Process I started using the CPU for 18ms burst [Q D G C A F H E]
time 9884ms: Process J (tau 28ms) completed I/O; added to ready queue[Q F H E J C A G D]
time 9900ms: Process B (tau 104ms) completed I/O; added to ready queue[Q F H E J B C A D G]
time 9901ms: Process I completed a CPU Burst; 51 bursts to go [Q B C A D G E J F H]
time 9901ms: Recalculate tau = 45ms for Process I [Q B C A D G E J F H]
time 9901ms: Process I switching out of CPU; will block on I/O until time 10100ms
time 9905ms: Process H started using the CPU for 19ms burst [Q B C D A G E F J]
time 9924ms: Process H completed a CPU Burst; 69 bursts to go [Q F J E G C B A D]
time 9924ms: Recalculate tau = 39ms for Process H [Q F J E G C B A D]
time 9924ms: Process H switching out of CPU; will block on I/O until time 10069ms
time 9928ms: Process E started using the CPU for 137ms burst [Q G J F A D B C]
time 10065ms: Process E completed a CPU Burst; 12 bursts to go [Q G J F A D B C]
time 10065ms: Recalculate tau = 89ms for Process E [Q G J F A D B C]
time 10065ms: Process E switching out of CPU; will block on I/O until time 10122ms
time 10069ms: Process H (tau 39ms) completed I/O; added to ready queue[Q J F A D B C H]
time 10069ms: Process G started using the CPU for 152ms burst [Q J F A D B C H]
time 10100ms: Process I (tau 45ms) completed I/O; added to ready queue[Q B C H I A D F J]
time 10122ms: Process E (tau 89ms) completed I/O; added to ready queue[Q I H B C E J F D A]
time 10221ms: Process G completed a CPU Burst; 63 bursts to go [Q I H B C E J F D A]
time 10221ms: Recalculate tau = 113ms for Process G [Q I H B C E J F D A]
time 10221ms: Process G switching out of CPU; will block on I/O until time 10328ms
time 10225ms: Process A started using the CPU for 200ms burst [Q I H C B E J D F]
time 10328ms: Process G (tau 113ms) completed I/O; added to ready queue[Q F D E J G I H B C]
time 10425ms: Process A completed a CPU Burst; 1 bursts to go [Q J G D E B C I H F]
time 10425ms: Recalculate tau = 128ms for Process A [Q J G D E B C I H F]
time 10425ms: Process A switching out of CPU; will block on I/O until time 10438ms
time 10429ms: Process F started using the CPU for 78ms burst [Q J G E D B C H I]
time 10438ms: Process A (tau 128ms) completed I/O; added to ready queue[Q B C H I A E D J G]
time 10507ms: Process F completed a CPU Burst; 28 bursts to go [Q D B G E I A C H J]
time 10507ms: Recalculate tau = 85ms for Process F [Q D B G E I A C H J]
time 10507ms: Process F switching out of CPU; will block on I/O until time 10600ms
time 10511ms: Process J started using the CPU for 18ms burst [Q D B E G I A H C]
time 10529ms: Process J completed a CPU Burst; 5 bursts to go [Q E G B D H C A I]
time 10529ms: Recalculate tau = 23ms for Process J [Q E G B D H C A I]
time 10529ms: Process J switching out of CPU; will block on I/O until time 10606ms
time 10533ms: Process B started using the CPU for 144ms burst [Q D G E A I C H]
time 10600ms: Process F (tau 85ms) completed I/O; added to ready queue[Q I C H F E A G D]
time 10606ms: Process J (tau 23ms) completed I/O; added to ready queue[Q F H I C J D G A E]
time 10677ms: Process B completed a CPU Burst; 8 bursts to go [Q A E D G F H I C J]
time 10677ms: Recalculate tau = 124ms for Process B [Q A E D G F H I C J]
time 10677ms: Process B switching out of CPU; will block on I/O until time 10758ms
time 10681ms: Process J started using the CPU for 20ms burst [Q A E G D F H C I]
time 10701ms: Process J completed a CPU Burst; 4 bursts to go [Q E A D G H F I C]
time 10701ms: Recalculate tau = 22ms for Process J [Q E A D G H F I C]
time 10701ms: Process J switching out of CPU; will block on I/O until time 10794ms
time 10705ms: Process D started using the CPU for 70ms burst [Q G A E I C F H]
time 10758ms: Process B (tau 124ms) completed I/O; added to ready queue[Q C F H B E I A G]
time 10775ms: Process D completed a CPU Burst; 21 bursts to go [Q E I A G H B F C]
time 10775ms: Recalculate tau = 69ms for Process D [Q E I A G H B F C]
time 10775ms: Process D switching out of CPU; will block on I/O until time 10808ms
time 10779ms: Process A started using the CPU for 197ms burst [Q G I E F C B H]
time 10794ms: Process J (tau 22ms) completed I/O; added to ready queue[Q C B H J E F I G]
time 10808ms: Process D (tau 69ms) completed I/O; added to ready queue[Q J H C B D G I F E]
time 10976ms: Process A terminated [Q C F D H I J E G B]
time 10980ms: Process F started using the CPU for 38ms burst [Q I J G E B D C H]
time 11018ms: Process F completed a CPU Burst; 27 bursts to go [Q E G I J H C B D]
time 11018ms: Recalculate tau = 62ms for Process F [Q E G I J H C B D]
time 11018ms: Process F switching out of CPU; will block on I/O until time 11031ms
time 11022ms: Process I started using the CPU for 66ms burst [Q J G E B D C H]
time 11031ms: Process F (tau 62ms) completed I/O; added to ready queue[Q D C H F E B G J]
time 11088ms: Process I completed a CPU Burst; 50 bursts to go [Q E B G J H F C D]
time 11088ms: Recalculate tau = 56ms for Process I [Q E B G J H F C D]
time 11088ms: Process I switching out of CPU; will block on I/O until time 11271ms
time 11092ms: Process G started using the CPU for 74ms burst [Q J B E C D F H]
time 11166ms: Process G completed a CPU Burst; 62 bursts to go [Q J B E C D F H]
time 11166ms: Recalculate tau = 94ms for Process G [Q J B E C D F H]
time 11166ms: Process G switching out of CPU; will block on I/O until time 11243ms
time 11170ms: Process J started using the CPU for 81ms burst [Q B E C D F H]
time 11243ms: Process G (tau 94ms) completed I/O; added to ready queue[Q B E C D F H G]
time 11251ms: Process J completed a CPU Burst; 3 bursts to go [Q B E C D F H G]
time 11251ms: Recalculate tau = 52ms for Process J [Q B E C D F H G]
time 11251ms: Process J switching out of CPU; will block on I/O until time 11319ms
time 11255ms: Process B started using the CPU for 183ms burst [Q E C D F H G]
time 11271ms: Process I (tau 56ms) completed I/O; added to ready queue[Q E C D F H G I]
time 11319ms: Process J (tau 52ms) completed I/O; added to ready queue[Q H G I J D F C E]
time 11438ms: Process B completed a CPU Burst; 7 bursts to go [Q E C D F H G I J]
time 11438ms: Recalculate tau = 154ms for Process B [Q E C D F H G I J]
time 11438ms: Process B switching out of CPU; will block on I/O until time 11446ms
time 11442ms: Process D started using the CPU for 40ms burst [Q F C E I J G H]
time 11446ms: Process B (tau 154ms) completed I/O; added to ready queue[Q J G H B E I C F]
time 11482ms: Process D completed a CPU Burst; 20 bursts to go [Q G J B H I E F C]
time 11482ms: Recalculate tau = 55ms for Process D [Q G J B H I E F C]
time 11482ms: Process D switching out of CPU; will block on I/O until time 11490ms
time 11486ms: Process B started using the CPU for 23ms burst [Q H J G F C E I]
time 11490ms: Process D (tau 55ms) completed I/O; added to ready queue[Q C E I D G F J H]
time 11509ms: Process B completed a CPU Burst; 6 bursts to go [Q J H F G E C D I]
time 11509ms: Recalculate tau = 89ms for Process B [Q J H F G E C D I]
time 11509ms: Process B switching out of CPU; will block on I/O until time 11575ms
time 11513ms: Process F started using the CPU for 120ms burst [Q G H J D I C E]
time 11575ms: Process B (tau 89ms) completed I/O; added to ready queue[Q I C E B J D H G]
time 11633ms: Process F completed a CPU Burst; 26 bursts to go [Q E B C I H G D J]
time 11633ms: Recalculate tau = 91ms for Process F [Q E B C I H G D J]
time 11633ms: Process F switching out of CPU; will block on I/O until time 11755ms
time 11637ms: Process C started using the CPU for 56ms burst [Q I B E D J G H]
time 11693ms: Process C completed a CPU Burst; 68 bursts to go [Q I B E D J G H]
time 11693ms: Recalculate tau = 50ms for Process C [Q I B E D J G H]
time 11693ms: Process C switching out of CPU; will block on I/O until time 11697ms
time 11697ms: Process C (tau 50ms) completed I/O; added to ready queue[Q B E D J G H C]
time 11697ms: Process I started using the CPU for 103ms burst [Q B E D J G H C]
time 11755ms: Process F (tau 91ms) completed I/O; added to ready queue[Q G H C F D J E B]
time 11800ms: Process I completed a CPU Burst; 49 bursts to go [Q J D B E F C G H]
time 11800ms: Recalculate tau = 80ms for Process I [Q J D B E F C G H]
time 11800ms: Process I switching out of CPU; will block on I/O until time 11842ms
time 11804ms: Process B started using the CPU for 80ms burst [Q E D J G H C F]
time 11842ms: Process I (tau 80ms) completed I/O; added to ready queue[Q H C F I J G D E]
time 11884ms: Process B completed a CPU Burst; 5 bursts to go [Q F I C H D E G J]
time 11884ms: Recalculate tau = 85ms for Process B [Q F I C H D E G J]
time 11884ms: Process B switching out of CPU; will block on I/O until time 11919ms
time 11888ms: Process C started using the CPU for 25ms burst [Q H I F G J E D]
time 11913ms: Process C completed a CPU Burst; 67 bursts to go [Q H I F G J E D]
time 11913ms: Recalculate tau = 38ms for Process C [Q H I F G J E D]
time 11913ms: Process C switching out of CPU; will block on I/O until time 11957ms
time 11917ms: Process H started using the CPU for 73ms burst [Q I F G J E D]
time 11919ms: Process B (tau 85ms) completed I/O; added to ready queue[Q I F G J E D B]
time 11957ms: Process C (tau 38ms) completed I/O; added to ready queue[Q E D B C G J F I]
time 11990ms: Process H completed a CPU Burst; 68 bursts to go [Q G J F I B C D E]
time 11990ms: Recalculate tau = 56ms for Process H [Q G J F I B C D E]
time 11990ms: Process H switching out of CPU; will block on I/O until time 12063ms
time 11994ms: Process F started using the CPU for 62ms burst [Q I J G D E C B]
time 12056ms: Process F completed a CPU Burst; 25 bursts to go [Q I J G D E C B]
time 12056ms: Recalculate tau = 77ms for Process F [Q I J G D E C B]
time 12056ms: Process F switching out of CPU; will block on I/O until time 12163ms
time 12060ms: Process I started using the CPU for 171ms burst [Q J G D E C B]
time 12063ms: Process H (tau 56ms) completed I/O; added to ready queue[Q J G D E C B H]
time 12163ms: Process F (tau 77ms) completed I/O; added to ready queue[Q C B H F D E G J]
time 12231ms: Process I completed a CPU Burst; 48 bursts to go [Q B C F H E D J G]
time 12231ms: Recalculate tau = 126ms for Process I [Q B C F H E D J G]
time 12231ms: Process I switching out of CPU; will block on I/O until time 12254ms
time 12235ms: Process F started using the CPU for 40ms burst [Q H C B J G D E]
time 12254ms: Process I (tau 126ms) completed I/O; added to ready queue[Q G D E I B J C H]
time 12275ms: Process F completed a CPU Burst; 24 bursts to go [Q J B H C I E G D]
time 12275ms: Recalculate tau = 59ms for Process F [Q J B H C I E G D]
time 12275ms: Process F switching out of CPU; will block on I/O until time 12403ms
time 12279ms: Process H started using the CPU for 3ms burst [Q C B J G D E I]
time 12282ms: Process H completed a CPU Burst; 67 bursts to go [Q C B J G D E I]
time 12282ms: Recalculate tau = 30ms for Process H [Q C B J G D E I]
time 12282ms: Process H switching out of CPU; will block on I/O until time 12395ms
time 12286ms: Process C started using the CPU for 5ms burst [Q B J G D E I]
time 12291ms: Process C completed a CPU Burst; 66 bursts to go [Q B J G D E I]
time 12291ms: Recalculate tau = 22ms for Process C [Q B J G D E I]
time 12291ms: Process C switching out of CPU; will block on I/O until time 12401ms
time 12295ms: Process B started using the CPU for 74ms burst [Q J G D E I]
time 12369ms: Process B completed a CPU Burst; 4 bursts to go [Q J G D E I]
time 12369ms: Recalculate tau = 80ms for Process B [Q J G D E I]
time 12369ms: Process B switching out of CPU; will block on I/O until time 12434ms
time 12373ms: Process J started using the CPU for 30ms burst [Q G D E I]
time 12395ms: Process H (tau 30ms) completed I/O; added to ready queue[Q G D E I H]
time 12401ms: Process C (tau 22ms) completed I/O; added to ready queue[Q G D E I H C]
time 12403ms: Process F (tau 59ms) completed I/O; added to ready queue[Q G D E I H C F]
time 12403ms: Process J completed a CPU Burst; 2 bursts to go [Q G D E I H C F]
time 12403ms: Recalculate tau = 41ms for Process J [Q G D E I H C F]
time 12403ms: Process J switching out of CPU; will block on I/O until time 12524ms
time 12407ms: Process G started using the CPU for 68ms burst [Q D E I H C F]
time 12434ms: Process B (tau 80ms) completed I/O; added to ready queue[Q D E I H C F B]
time 12475ms: Process G completed a CPU Burst; 61 bursts to go [Q D E I H C F B]
time 12475ms: Recalculate tau = 81ms for Process G [Q D E I H C F B]
time 12475ms: Process G switching out of CPU; will block on I/O until time 12618ms
time 12479ms: Process D started using the CPU for 65ms burst [Q E I H C F B]
time 12524ms: Process J (tau 41ms) completed I/O; added to ready queue[Q E I H C F B J]
time 12544ms: Process D completed a CPU Burst; 19 bursts to go [Q E I H C F B J]
time 12544ms: Recalculate tau = 60ms for Process D [Q E I H C F B J]
time 12544ms: Process D switching out of CPU; will block on I/O until time 12590ms
time 12548ms: Process E started using the CPU for 124ms burst [Q I H C F B J]
time 12590ms: Process D (tau 60ms) completed I/O; added to ready queue[Q I H C F B J D]
time 12618ms: Process G (tau 81ms) completed I/O; added to ready queue[Q B J D G C F H I]
time 12672ms: Process E completed a CPU Burst; 11 bursts to go [Q G D B J I H C F]
time 12672ms: Recalculate tau = 107ms for Process E [Q G D B J I H C F]
time 12672ms: Process E switching out of CPU; will block on I/O until time 12749ms
time 12676ms: Process B started using the CPU for 170ms burst [Q J D G C F H I]
time 12749ms: Process E (tau 107ms) completed I/O; added to ready queue[Q F H I E G C D J]
time 12846ms: Process B completed a CPU Burst; 3 bursts to go [Q G C D J I E H F]
time 12846ms: Recalculate tau = 125ms for Process B [Q G C D J I E H F]
time 12846ms: Process B switching out of CPU; will block on I/O until time 12905ms
time 12850ms: Process D started using the CPU for 13ms burst [Q J C G H F E I]
time 12863ms: Process D completed a CPU Burst; 18 bursts to go [Q J C G H F E I]
time 12863ms: Recalculate tau = 37ms for Process D [Q J C G H F E I]
time 12863ms: Process D switching out of CPU; will block on I/O until time 12903ms
time 12867ms: Process J started using the CPU for 156ms burst [Q C G H F E I]
time 12903ms: Process D (tau 37ms) completed I/O; added to ready queue[Q C G H F E I D]
time 12905ms: Process B (tau 125ms) completed I/O; added to ready queue[Q E I D B H F G C]
time 13023ms: Process J completed a CPU Burst; 1 bursts to go [Q B D E I C G H F]
time 13023ms: Recalculate tau = 99ms for Process J [Q B D E I C G H F]
time 13023ms: Process J switching out of CPU; will block on I/O until time 13092ms
time 13027ms: Process E started using the CPU for 108ms burst [Q I D B H F G C]
time 13092ms: Process J (tau 99ms) completed I/O; added to ready queue[Q F G C J B H D I]
time 13135ms: Process E completed a CPU Burst; 10 bursts to go [Q D I H B G F J C]
time 13135ms: Recalculate tau = 108ms for Process E [Q D I H B G F J C]
time 13135ms: Process E switching out of CPU; will block on I/O until time 13254ms
time 13139ms: Process H started using the CPU for 106ms burst [Q B I D J C F G]
time 13245ms: Process H completed a CPU Burst; 66 bursts to go [Q B I D J C F G]
time 13245ms: Recalculate tau = 68ms for Process H [Q B I D J C F G]
time 13245ms: Process H switching out of CPU; will block on I/O until time 13328ms
time 13249ms: Process B started using the CPU for 43ms burst [Q I D J C F G]
time 13254ms: Process E (tau 108ms) completed I/O; added to ready queue[Q I D J C F G E]
time 13292ms: Process B completed a CPU Burst; 2 bursts to go [Q I D J C F G E]
time 13292ms: Recalculate tau = 84ms for Process B [Q I D J C F G E]
time 13292ms: Process B switching out of CPU; will block on I/O until time 13388ms
time 13296ms: Process I started using the CPU for 200ms burst [Q D J C F G E]
time 13328ms: Process H (tau 68ms) completed I/O; added to ready queue[Q D J C F G E H]
time 13388ms: Process B (tau 84ms) completed I/O; added to ready queue[Q G E H B C F J D]
time 13496ms: Process I completed a CPU Burst; 47 bursts to go [Q E G B H F C D J]
time 13496ms: Recalculate tau = 163ms for Process I [Q E G B H F C D J]
time 13496ms: Process I switching out of CPU; will block on I/O until time 13629ms
time 13500ms: Process B started using the CPU for 158ms burst [Q H G E D J C F]
time 13629ms: Process I (tau 163ms) completed I/O; added to ready queue[Q J C F I E D G H]
time 13658ms: Process B completed a CPU Burst; 1 bursts to go [Q D E H G I F J C]
time 13658ms: Recalculate tau = 121ms for Process B [Q D E H G I F J C]
time 13658ms: Process B switching out of CPU; will block on I/O until time 13777ms
time 13662ms: Process H started using the CPU for 98ms burst [Q G E D J C F I]
time 13760ms: Process H completed a CPU Burst; 65 bursts to go [Q G E D J C F I]
time 13760ms: Recalculate tau = 83ms for Process H [Q G E D J C F I]
time 13760ms: Process H switching out of CPU; will block on I/O until time 13817ms
time 13764ms: Process G started using the CPU for 8ms burst [Q E D J C F I]
time 13772ms: Process G completed a CPU Burst; 60 bursts to go [Q E D J C F I]
time 13772ms: Recalculate tau = 45ms for Process G [Q E D J C F I]
time 13772ms: Process G switching out of CPU; will block on I/O until time 13837ms
time 13776ms: Process E started using the CPU for 110ms burst [Q D J C F I]
time 13777ms: Process B (tau 121ms) completed I/O; added to ready queue[Q D J C F I B]
time 13817ms: Process H (tau 83ms) completed I/O; added to ready queue[Q D J C F I B H]
time 13837ms: Process G (tau 45ms) completed I/O; added to ready queue[Q I B H G C F J D]
time 13886ms: Process E completed a CPU Burst; 9 bursts to go [Q C F J D H G B I]
time 13886ms: Recalculate tau = 109ms for Process E [Q C F J D H G B I]
time 13886ms: Process E switching out of CPU; will block on I/O until time 14045ms
time 13890ms: Process J started using the CPU for 106ms burst [Q D F C B I G H]
time 13996ms: Process J terminated [Q D F C B I G H]
time 14000ms: Process D started using the CPU for 128ms burst [Q F C B I G H]
time 14045ms: Process E (tau 109ms) completed I/O; added to ready queue[Q F C B I G H E]
time 14128ms: Process D completed a CPU Burst; 17 bursts to go [Q F C B I G H E]
time 14128ms: Recalculate tau = 83ms for Process D [Q F C B I G H E]
time 14128ms: Process D switching out of CPU; will block on I/O until time 14145ms
time 14132ms: Process F started using the CPU for 167ms burst [Q C B I G H E]
time 14145ms: Process D (tau 83ms) completed I/O; added to ready queue[Q C B I G H E D]
time 14299ms: Process F completed a CPU Burst; 23 bursts to go [Q C B I G H E D]
time 14299ms: Recalculate tau = 113ms for Process F [Q C B I G H E D]
time 14299ms: Process F switching out of CPU; will block on I/O until time 14375ms
time 14303ms: Process C started using the CPU for 9ms burst [Q B I G H E D]
time 14312ms: Process C completed a CPU Burst; 65 bursts to go [Q B I G H E D]
time 14312ms: Recalculate tau = 16ms for Process C [Q B I G H E D]
time 14312ms: Process C switching out of CPU; will block on I/O until time 14320ms
time 14316ms: Process B started using the CPU for 17ms burst [Q I G H E D]
time 14320ms: Process C (tau 16ms) completed I/O; added to ready queue[Q I G H E D C]
time 14333ms: Process B terminated [Q I G H E D C]
time 14337ms: Process I started using the CPU for 117ms burst [Q G H E D C]
time 14375ms: Process F (tau 113ms) completed I/O; added to ready queue[Q G H E D C F]
time 14454ms: Process I completed a CPU Burst; 46 bursts to go [Q G H E D C F]
time 14454ms: Recalculate tau = 140ms for Process I [Q G H E D C F]
time 14454ms: Process I switching out of CPU; will block on I/O until time 14590ms
time 14458ms: Process G started using the CPU for 71ms burst [Q H E D C F]
time 14529ms: Process G completed a CPU Burst; 59 bursts to go [Q H E D C F]
time 14529ms: Recalculate tau = 58ms for Process G [Q H E D C F]
time 14529ms: Process G switching out of CPU; will block on I/O until time 14624ms
time 14533ms: Process H started using the CPU for 20ms burst [Q E D C F]
time 14553ms: Process H completed a CPU Burst; 64 bursts to go [Q E D C F]
time 14553ms: Recalculate tau = 52ms for Process H [Q E D C F]
time 14553ms: Process H switching out of CPU; will block on I/O until time 14706ms
time 14557ms: Process E started using the CPU for 77ms burst [Q D C F]
time 14590ms: Process I (tau 140ms) completed I/O; added to ready queue[Q D C F I]
time 14624ms: Process G (tau 58ms) completed I/O; added to ready queue[Q D C F I G]
time 14634ms: Process E completed a CPU Burst; 8 bursts to go [Q D C F I G]
time 14634ms: Recalculate tau = 93ms for Process E [Q D C F I G]
time 14634ms: Process E switching out of CPU; will block on I/O until time 14658ms
time 14638ms: Process D started using the CPU for 94ms burst [Q C F I G]
time 14658ms: Process E (tau 93ms) completed I/O; added to ready queue[Q C F I G E]
time 14706ms: Process H (tau 52ms) completed I/O; added to ready queue[Q C F I G E H]
time 14732ms: Process D completed a CPU Burst; 16 bursts to go [Q C F I G E H]
time 14732ms: Recalculate tau = 89ms for Process D [Q C F I G E H]
time 14732ms: Process D switching out of CPU; will block on I/O until time 14846ms
time 14736ms: Process C started using the CPU for 32ms burst [Q F I G E H]
time 14768ms: Process C completed a CPU Burst; 64 bursts to go [Q F I G E H]
time 14768ms: Recalculate tau = 24ms for Process C [Q F I G E H]
time 14768ms: Process C switching out of CPU; will block on I/O until time 14882ms
time 14772ms: Process F started using the CPU for 45ms burst [Q I G E H]
time 14817ms: Process F completed a CPU Burst; 22 bursts to go [Q I G E H]
time 14817ms: Recalculate tau = 79ms for Process F [Q I G E H]
time 14817ms: Process F switching out of CPU; will block on I/O until time 14913ms
time 14821ms: Process I started using the CPU for 6ms burst [Q G E H]
time 14827ms: Process I completed a CPU Burst; 45 bursts to go [Q G E H]
time 14827ms: Recalculate tau = 73ms for Process I [Q G E H]
time 14827ms: Process I switching out of CPU; will block on I/O until time 14862ms
time 14831ms: Process G started using the CPU for 64ms burst [Q E H]
time 14846ms: Process D (tau 89ms) completed I/O; added to ready queue[Q E H D]
time 14862ms: Process I (tau 73ms) completed I/O; added to ready queue[Q E H D I]
time 14882ms: Process C (tau 24ms) completed I/O; added to ready queue[Q E H D I C]
time 14895ms: Process G completed a CPU Burst; 58 bursts to go [Q E H D I C]
time 14895ms: Recalculate tau = 61ms for Process G [Q E H D I C]
time 14895ms: Process G switching out of CPU; will block on I/O until time 14934ms
time 14899ms: Process E started using the CPU for 187ms burst [Q H D I C]
time 14913ms: Process F (tau 79ms) completed I/O; added to ready queue[Q H D I C F]
time 14934ms: Process G (tau 61ms) completed I/O; added to ready queue[Q H D I C F G]
time 15086ms: Process E completed a CPU Burst; 7 bursts to go [Q H D I C F G]
time 15086ms: Recalculate tau = 140ms for Process E [Q H D I C F G]
time 15086ms: Process E switching out of CPU; will block on I/O until time 15150ms
time 15090ms: Process H started using the CPU for 50ms burst [Q D I C F G]
time 15140ms: Process H completed a CPU Burst; 63 bursts to go [Q D I C F G]
time 15140ms: Recalculate tau = 51ms for Process H [Q D I C F G]
time 15140ms: Process H switching out of CPU; will block on I/O until time 15204ms
time 15144ms: Process D started using the CPU for 43ms burst [Q I C F G]
time 15150ms: Process E (tau 140ms) completed I/O; added to ready queue[Q I C F G E]
time 15187ms: Process D completed a CPU Burst; 15 bursts to go [Q I C F G E]
time 15187ms: Recalculate tau = 66ms for Process D [Q I C F G E]
time 15187ms: Process D switching out of CPU; will block on I/O until time 15219ms
time 15191ms: Process I started using the CPU for 141ms burst [Q C F G E]
time 15204ms: Process H (tau 51ms) completed I/O; added to ready queue[Q C F G E H]
time 15219ms: Process D (tau 66ms) completed I/O; added to ready queue[Q C F G E H D]
time 15332ms: Process I completed a CPU Burst; 44 bursts to go [Q C F G E H D]
time 15332ms: Recalculate tau = 107ms for Process I [Q C F G E H D]
time 15332ms: Process I switching out of CPU; will block on I/O until time 15356ms
time 15336ms: Process C started using the CPU for 111ms burst [Q F G E H D]
time 15356ms: Process I (tau 107ms) completed I/O; added to ready queue[Q F G E H D I]
time 15447ms: Process C completed a CPU Burst; 63 bursts to go [Q F G E H D I]
time 15447ms: Recalculate tau = 68ms for Process C [Q F G E H D I]
time 15447ms: Process C switching out of CPU; will block on I/O until time 15461ms
time 15451ms: Process F started using the CPU for 96ms burst [Q G E H D I]
time 15461ms: Process C (tau 68ms) completed I/O; added to ready queue[Q G E H D I C]
time 15547ms: Process F completed a CPU Burst; 21 bursts to go [Q G E H D I C]
time 15547ms: Recalculate tau = 88ms for Process F [Q G E H D I C]
time 15547ms: Process F switching out of CPU; will block on I/O until time 15732ms
time 15551ms: Process G started using the CPU for 17ms burst [Q E H D I C]
time 15568ms: Process G completed a CPU Burst; 57 bursts to go [Q E H D I C]
time 15568ms: Recalculate tau = 39ms for Process G [Q E H D I C]
time 15568ms: Process G switching out of CPU; will block on I/O until time 15590ms
time 15572ms: Process E started using the CPU for 22ms burst [Q H D I C]
time 15590ms: Process G (tau 39ms) completed I/O; added to ready queue[Q H D I C G]
time 15594ms: Process E completed a CPU Burst; 6 bursts to go [Q H D I C G]
time 15594ms: Recalculate tau = 81ms for Process E [Q H D I C G]
time 15594ms: Process E switching out of CPU; will block on I/O until time 15712ms
time 15598ms: Process H started using the CPU for 55ms burst [Q D I C G]
time 15653ms: Process H completed a CPU Burst; 62 bursts to go [Q D I C G]
time 15653ms: Recalculate tau = 53ms for Process H [Q D I C G]
time 15653ms: Process H switching out of CPU; will block on I/O until time 15673ms
time 15657ms: Process D started using the CPU for 47ms burst [Q I C G]
time 15673ms: Process H (tau 53ms) completed I/O; added to ready queue[Q I C G H]
time 15704ms: Process D completed a CPU Burst; 14 bursts to go [Q I C G H]
time 15704ms: Recalculate tau = 57ms for Process D [Q I C G H]
time 15704ms: Process D switching out of CPU; will block on I/O until time 15756ms
time 15708ms: Process I started using the CPU for 13ms burst [Q C G H]
time 15712ms: Process E (tau 81ms) completed I/O; added to ready queue[Q C G H E]
time 15721ms: Process I completed a CPU Burst; 43 bursts to go [Q C G H E]
time 15721ms: Recalculate tau = 60ms for Process I [Q C G H E]
time 15721ms: Process I switching out of CPU; will block on I/O until time 15735ms
time 15725ms: Process C started using the CPU for 45ms burst [Q G H E]
time 15732ms: Process F (tau 88ms) completed I/O; added to ready queue[Q G H E F]
time 15735ms: Process I (tau 60ms) completed I/O; added to ready queue[Q G H E F I]
time 15756ms: Process D (tau 57ms) completed I/O; added to ready queue[Q G H E F I D]
time 15770ms: Process C completed a CPU Burst; 62 bursts to go [Q G H E F I D]
time 15770ms: Recalculate tau = 57ms for Process C [Q G H E F I D]
time 15770ms: Process C switching out of CPU; will block on I/O until time 15781ms
time 15774ms: Process G started using the CPU for 2ms burst [Q H E F I D]
time 15776ms: Process G completed a CPU Burst; 56 bursts to go [Q H E F I D]
time 15776ms: Recalculate tau = 21ms for Process G [Q H E F I D]
time 15776ms: Process G switching out of CPU; will block on I/O until time 15926ms
time 15780ms: Process H started using the CPU for 47ms burst [Q E F I D]
time 15781ms: Process C (tau 57ms) completed I/O; added to ready queue[Q E F I D C]
time 15827ms: Process H completed a CPU Burst; 61 bursts to go [Q E F I D C]
time 15827ms: Recalculate tau = 50ms for Process H [Q E F I D C]
time 15827ms: Process H switching out of CPU; will block on I/O until time 15962ms
time 15831ms: Process E started using the CPU for 80ms burst [Q F I D C]
time 15911ms: Process E completed a CPU Burst; 5 bursts to go [Q F I D C]
time 15911ms: Recalculate tau = 81ms for Process E [Q F I D C]
time 15911ms: Process E switching out of CPU; will block on I/O until time 16040ms
time 15915ms: Process F started using the CPU for 37ms burst [Q I D C]
time 15926ms: Process G (tau 21ms) completed I/O; added to ready queue[Q I D C G]
time 15952ms: Process F completed a CPU Burst; 20 bursts to go [Q I D C G]
time 15952ms: Recalculate tau = 63ms for Process F [Q I D C G]
time 15952ms: Process F switching out of CPU; will block on I/O until time 16013ms
time 15956ms: Process I started using the CPU for 103ms burst [Q D C G]
time 15962ms: Process H (tau 50ms) completed I/O; added to ready queue[Q D C G H]
time 16013ms: Process F (tau 63ms) completed I/O; added to ready queue[Q D C G H F]
time 16040ms: Process E (tau 81ms) completed I/O; added to ready queue[Q D C G H F E]
time 16059ms: Process I completed a CPU Burst; 42 bursts to go [Q D C G H F E]
time 16059ms: Recalculate tau = 82ms for Process I [Q D C G H F E]
time 16059ms: Process I switching out of CPU; will block on I/O until time 16075ms
time 16063ms: Process D started using the CPU for 5ms burst [Q C G H F E]
time 16068ms: Process D completed a CPU Burst; 13 bursts to go [Q C G H F E]
time 16068ms: Recalculate tau = 31ms for Process D [Q C G H F E]
time 16068ms: Process D switching out of CPU; will block on I/O until time 16268ms
time 16072ms: Process C started using the CPU for 67ms burst [Q G H F E]
time 16075ms: Process I (tau 82ms) completed I/O; added to ready queue[Q G H F E I]
time 16139ms: Process C completed a CPU Burst; 61 bursts to go [Q G H F E I]
time 16139ms: Recalculate tau = 62ms for Process C [Q G H F E I]
time 16139ms: Process C switching out of CPU; will block on I/O until time 16203ms
time 16143ms: Process G started using the CPU for 21ms burst [Q H F E I]
time 16164ms: Process G completed a CPU Burst; 55 bursts to go [Q H F E I]
time 16164ms: Recalculate tau = 21ms for Process G [Q H F E I]
time 16164ms: Process G switching out of CPU; will block on I/O until time 16307ms
time 16168ms: Process H started using the CPU for 11ms burst [Q F E I]
time 16179ms: Process H completed a CPU Burst; 60 bursts to go [Q F E I]
time 16179ms: Recalculate tau = 31ms for Process H [Q F E I]
time 16179ms: Process H switching out of CPU; will block on I/O until time 16357ms
time 16183ms: Process F started using the CPU for 15ms burst [Q E I]
time 16198ms: Process F completed a CPU Burst; 19 bursts to go [Q E I]
time 16198ms: Recalculate tau = 39ms for Process F [Q E I]
time 16198ms: Process F switching out of CPU; will block on I/O until time 16224ms
time 16202ms: Process E started using the CPU for 46ms burst [Q I]
time 16203ms: Process C (tau 62ms) completed I/O; added to ready queue[Q I C]
time 16224ms: Process F (tau 39ms) completed I/O; added to ready queue[Q I C F]
time 16248ms: Process E completed a CPU Burst; 4 bursts to go [Q I C F]
time 16248ms: Recalculate tau = 64ms for Process E [Q I C F]
time 16248ms: Process E switching out of CPU; will block on I/O until time 16405ms
time 16252ms: Process I started using the CPU for 15ms burst [Q C F]
time 16267ms: Process I completed a CPU Burst; 41 bursts to go [Q C F]
time 16267ms: Recalculate tau = 49ms for Process I [Q C F]
time 16267ms: Process I switching out of CPU; will block on I/O until time 16380ms
time 16268ms: Process D (tau 31ms) completed I/O; added to ready queue[Q C F D]
time 16271ms: Process C started using the CPU for 60ms burst [Q F D]
time 16307ms: Process G (tau 21ms) completed I/O; added to ready queue[Q F D G]
time 16331ms: Process C completed a CPU Burst; 60 bursts to go [Q F D G]
time 16331ms: Recalculate tau = 61ms for Process C [Q F D G]
time 16331ms: Process C switching out of CPU; will block on I/O until time 16526ms
time 16335ms: Process F started using the CPU for 62ms burst [Q D G]
time 16357ms: Process H (tau 31ms) completed I/O; added to ready queue[Q D G H]
time 16380ms: Process I (tau 49ms) completed I/O; added to ready queue[Q D G H I]
time 16397ms: Process F completed a CPU Burst; 18 bursts to go [Q D G H I]
time 16397ms: Recalculate tau = 51ms for Process F [Q D G H I]
time 16397ms: Process F switching out of CPU; will block on I/O until time 16479ms
time 16401ms: Process D started using the CPU for 122ms burst [Q G H I]
time 16405ms: Process E (tau 64ms) completed I/O; added to ready queue[Q G H I E]
time 16479ms: Process F (tau 51ms) completed I/O; added to ready queue[Q G H I E F]
time 16523ms: Process D completed a CPU Burst; 12 bursts to go [Q G H I E F]
time 16523ms: Recalculate tau = 77ms for Process D [Q G H I E F]
time 16523ms: Process D switching out of CPU; will block on I/O until time 16560ms
time 16526ms: Process C (tau 61ms) completed I/O; added to ready queue[Q H I E F C]
time 16527ms: Process G started using the CPU for 22ms burst [Q H I E F C]
time 16549ms: Process G completed a CPU Burst; 54 bursts to go [Q H I E F C]
time 16549ms: Recalculate tau = 22ms for Process G [Q H I E F C]
time 16549ms: Process G switching out of CPU; will block on I/O until time 16637ms
time 16553ms: Process H started using the CPU for 18ms burst [Q I E F C]
time 16560ms: Process D (tau 77ms) completed I/O; added to ready queue[Q I E F C D]
time 16571ms: Process H completed a CPU Burst; 59 bursts to go [Q I E F C D]
time 16571ms: Recalculate tau = 25ms for Process H [Q I E F C D]
time 16571ms: Process H switching out of CPU; will block on I/O until time 16724ms
time 16575ms: Process I started using the CPU for 26ms burst [Q E F C D]
time 16601ms: Process I completed a CPU Burst; 40 bursts to go [Q E F C D]
time 16601ms: Recalculate tau = 38ms for Process I [Q E F C D]
time 16601ms: Process I switching out of CPU; will block on I/O until time 16663ms
time 16605ms: Process E started using the CPU for 54ms burst [Q F C D]
time 16637ms: Process G (tau 22ms) completed I/O; added to ready queue[Q F C D G]
time 16659ms: Process E completed a CPU Burst; 3 bursts to go [Q F C D G]
time 16659ms: Recalculate tau = 59ms for Process E [Q F C D G]
time 16659ms: Process E switching out of CPU; will block on I/O until time 16667ms
time 16663ms: Process F started using the CPU for 83ms burst [Q C D G I]
time 16663ms: Process I (tau 38ms) completed I/O; added to ready queue[Q C D G I]
time 16667ms: Process E (tau 59ms) completed I/O; added to ready queue[Q C D G I E]
time 16724ms: Process H (tau 25ms) completed I/O; added to ready queue[Q C D G I E H]
time 16746ms: Process F completed a CPU Burst; 17 bursts to go [Q C D G I E H]
time 16746ms: Recalculate tau = 67ms for Process F [Q C D G I E H]
time 16746ms: Process F switching out of CPU; will block on I/O until time 16781ms
time 16750ms: Process C started using the CPU for 54ms burst [Q D G I E H]
time 16781ms: Process F (tau 67ms) completed I/O; added to ready queue[Q D G I E H F]
time 16804ms: Process C completed a CPU Burst; 59 bursts to go [Q D G I E H F]
time 16804ms: Recalculate tau = 58ms for Process C [Q D G I E H F]
time 16804ms: Process C switching out of CPU; will block on I/O until time 16901ms
time 16808ms: Process D started using the CPU for 31ms burst [Q G I E H F]
time 16839ms: Process D completed a CPU Burst; 11 bursts to go [Q G I E H F]
time 16839ms: Recalculate tau = 54ms for Process D [Q G I E H F]
time 16839ms: Process D switching out of CPU; will block on I/O until time 16848ms
time 16843ms: Process G started using the CPU for 72ms burst [Q I E H F]
time 16848ms: Process D (tau 54ms) completed I/O; added to ready queue[Q I E H F D]
time 16901ms: Process C (tau 58ms) completed I/O; added to ready queue[Q I E H F D C]
time 16915ms: Process G completed a CPU Burst; 53 bursts to go [Q I E H F D C]
time 16915ms: Recalculate tau = 47ms for Process G [Q I E H F D C]
time 16915ms: Process G switching out of CPU; will block on I/O until time 17109ms
time 16919ms: Process I started using the CPU for 74ms burst [Q E H F D C]
time 16993ms: Process I completed a CPU Burst; 39 bursts to go [Q E H F D C]
time 16993ms: Recalculate tau = 56ms for Process I [Q E H F D C]
time 16993ms: Process I switching out of CPU; will block on I/O until time 17116ms
time 16997ms: Process E started using the CPU for 164ms burst [Q H F D C]
time 17109ms: Process G (tau 47ms) completed I/O; added to ready queue[Q H F D C G]
time 17116ms: Process I (tau 56ms) completed I/O; added to ready queue[Q H F D C G I]
time 17161ms: Process E completed a CPU Burst; 2 bursts to go [Q H F D C G I]
time 17161ms: Recalculate tau = 112ms for Process E [Q H F D C G I]
time 17161ms: Process E switching out of CPU; will block on I/O until time 17178ms
time 17165ms: Process H started using the CPU for 46ms burst [Q F D C G I]
time 17178ms: Process E (tau 112ms) completed I/O; added to ready queue[Q F D C G I E]
time 17211ms: Process H completed a CPU Burst; 58 bursts to go [Q F D C G I E]
time 17211ms: Recalculate tau = 36ms for Process H [Q F D C G I E]
time 17211ms: Process H switching out of CPU; will block on I/O until time 17319ms
time 17215ms: Process F started using the CPU for 165ms burst [Q D C G I E]
time 17319ms: Process H (tau 36ms) completed I/O; added to ready queue[Q D C G I E H]
time 17380ms: Process F completed a CPU Burst; 16 bursts to go [Q D C G I E H]
time 17380ms: Recalculate tau = 116ms for Process F [Q D C G I E H]
time 17380ms: Process F switching out of CPU; will block on I/O until time 17457ms
time 17384ms: Process D started using the CPU for 61ms burst [Q C G I E H]
time 17445ms: Process D completed a CPU Burst; 10 bursts to go [Q C G I E H]
time 17445ms: Recalculate tau = 58ms for Process D [Q C G I E H]
time 17445ms: Process D switching out of CPU; will block on I/O until time 17521ms
time 17449ms: Process C started using the CPU for 126ms burst [Q G I E H]
time 17457ms: Process F (tau 116ms) completed I/O; added to ready queue[Q G I E H F]
time 17521ms: Process D (tau 58ms) completed I/O; added to ready queue[Q G I E H F D]
time 17575ms: Process C completed a CPU Burst; 58 bursts to go [Q G I E H F D]
time 17575ms: Recalculate tau = 92ms for Process C [Q G I E H F D]
time 17575ms: Process C switching out of CPU; will block on I/O until time 17775ms
time 17579ms: Process G started using the CPU for 13ms burst [Q I E H F D]
time 17592ms: Process G completed a CPU Burst; 52 bursts to go [Q I E H F D]
time 17592ms: Recalculate tau = 30ms for Process G [Q I E H F D]
time 17592ms: Process G switching out of CPU; will block on I/O until time 17703ms
time 17596ms: Process I started using the CPU for 6ms burst [Q E H F D]
time 17602ms: Process I completed a CPU Burst; 38 bursts to go [Q E H F D]
time 17602ms: Recalculate tau = 31ms for Process I [Q E H F D]
time 17602ms: Process I switching out of CPU; will block on I/O until time 17708ms
time 17606ms: Process E started using the CPU for 131ms burst [Q H F D]
time 17703ms: Process G (tau 30ms) completed I/O; added to ready queue[Q H F D G]
time 17708ms: Process I (tau 31ms) completed I/O; added to ready queue[Q H F D G I]
time 17737ms: Process E completed a CPU Burst; 1 bursts to go [Q H F D G I]
time 17737ms: Recalculate tau = 122ms for Process E [Q H F D G I]
time 17737ms: Process E switching out of CPU; will block on I/O until time 17747ms
time 17741ms: Process H started using the CPU for 51ms burst [Q F D G I]
time 17747ms: Process E (tau 122ms) completed I/O; added to ready queue[Q F D G I E]
time 17775ms: Process C (tau 92ms) completed I/O; added to ready queue[Q F D G I E C]
time 17792ms: Process H completed a CPU Burst; 57 bursts to go [Q F D G I E C]
time 17792ms: Recalculate tau = 44ms for Process H [Q F D G I E C]
time 17792ms: Process H switching out of CPU; will block on I/O until time 17892ms
time 17796ms: Process F started using the CPU for 7ms burst [Q D G I E C]
time 17803ms: Process F completed a CPU Burst; 15 bursts to go [Q D G I E C]
time 17803ms: Recalculate tau = 62ms for Process F [Q D G I E C]
time 17803ms: Process F switching out of CPU; will block on I/O until time 17821ms
time 17807ms: Process D started using the CPU for 7ms burst [Q G I E C]
time 17814ms: Process D completed a CPU Burst; 9 bursts to go [Q G I E C]
time 17814ms: Recalculate tau = 33ms for Process D [Q G I E C]
time 17814ms: Process D switching out of CPU; will block on I/O until time 17980ms
time 17818ms: Process G started using the CPU for 44ms burst [Q I E C]
time 17821ms: Process F (tau 62ms) completed I/O; added to ready queue[Q I E C F]
time 17862ms: Process G completed a CPU Burst; 51 bursts to go [Q I E C F]
time 17862ms: Recalculate tau = 37ms for Process G [Q I E C F]
time 17862ms: Process G switching out of CPU; will block on I/O until time 17959ms
time 17866ms: Process I started using the CPU for 120ms burst [Q E C F]
time 17892ms: Process H (tau 44ms) completed I/O; added to ready queue[Q E C F H]
time 17959ms: Process G (tau 37ms) completed I/O; added to ready queue[Q E C F H G]
time 17980ms: Process D (tau 33ms) completed I/O; added to ready queue[Q E C F H G D]
time 17986ms: Process I completed a CPU Burst; 37 bursts to go [Q E C F H G D]
time 17986ms: Recalculate tau = 76ms for Process I [Q E C F H G D]
time 17986ms: Process I switching out of CPU; will block on I/O until time 17991ms
time 17990ms: Process E started using the CPU for 17ms burst [Q C F H G D]
time 17991ms: Process I (tau 76ms) completed I/O; added to ready queue[Q C F H G D I]
time 18007ms: Process E terminated [Q C F H G D I]
time 18011ms: Process C started using the CPU for 168ms burst [Q F H G D I]
time 18179ms: Process C completed a CPU Burst; 57 bursts to go [Q F H G D I]
time 18179ms: Recalculate tau = 130ms for Process C [Q F H G D I]
time 18179ms: Process C switching out of CPU; will block on I/O until time 18231ms
time 18183ms: Process F started using the CPU for 103ms burst [Q H G D I]
time 18231ms: Process C (tau 130ms) completed I/O; added to ready queue[Q H G D I C]
time 18286ms: Process F completed a CPU Burst; 14 bursts to go [Q H G D I C]
time 18286ms: Recalculate tau = 83ms for Process F [Q H G D I C]
time 18286ms: Process F switching out of CPU; will block on I/O until time 18466ms
time 18290ms: Process H started using the CPU for 14ms burst [Q G D I C]
time 18304ms: Process H completed a CPU Burst; 56 bursts to go [Q G D I C]
time 18304ms: Recalculate tau = 29ms for Process H [Q G D I C]
time 18304ms: Process H switching out of CPU; will block on I/O until time 18317ms
time 18308ms: Process G started using the CPU for 28ms burst [Q D I C]
time 18317ms: Process H (tau 29ms) completed I/O; added to ready queue[Q D I C H]
time 18336ms: Process G completed a CPU Burst; 50 bursts to go [Q D I C H]
time 18336ms: Recalculate tau = 33ms for Process G [Q D I C H]
time 18336ms: Process G switching out of CPU; will block on I/O until time 18368ms
time 18340ms: Process D started using the CPU for 2ms burst [Q I C H]
time 18342ms: Process D completed a CPU Burst; 8 bursts to go [Q I C H]
time 18342ms: Recalculate tau = 18ms for Process D [Q I C H]
time 18342ms: Process D switching out of CPU; will block on I/O until time 18355ms
time 18346ms: Process I started using the CPU for 25ms burst [Q C H]
time 18355ms: Process D (tau 18ms) completed I/O; added to ready queue[Q C H D]
time 18368ms: Process G (tau 33ms) completed I/O; added to ready queue[Q C H D G]
time 18371ms: Process I completed a CPU Burst; 36 bursts to go [Q C H D G]
time 18371ms: Recalculate tau = 51ms for Process I [Q C H D G]
time 18371ms: Process I switching out of CPU; will block on I/O until time 18440ms
time 18375ms: Process C started using the CPU for 23ms burst [Q H D G]
time 18398ms: Process C completed a CPU Burst; 56 bursts to go [Q H D G]
time 18398ms: Recalculate tau = 77ms for Process C [Q H D G]
time 18398ms: Process C switching out of CPU; will block on I/O until time 18409ms
time 18402ms: Process H started using the CPU for 4ms burst [Q D G]
time 18406ms: Process H completed a CPU Burst; 55 bursts to go [Q D G]
time 18406ms: Recalculate tau = 17ms for Process H [Q D G]
time 18406ms: Process H switching out of CPU; will block on I/O until time 18427ms
time 18409ms: Process C (tau 77ms) completed I/O; added to ready queue[Q G C]
time 18410ms: Process D started using the CPU for 48ms burst [Q G C]
time 18427ms: Process H (tau 17ms) completed I/O; added to ready queue[Q G C H]
time 18440ms: Process I (tau 51ms) completed I/O; added to ready queue[Q G C H I]
time 18458ms: Process D completed a CPU Burst; 7 bursts to go [Q G C H I]
time 18458ms: Recalculate tau = 33ms for Process D [Q G C H I]
time 18458ms: Process D switching out of CPU; will block on I/O until time 18466ms
time 18462ms: Process G started using the CPU for 19ms burst [Q C H I]
time 18466ms: Process F (tau 83ms) completed I/O; added to ready queue[Q C H I D F]
time 18466ms: Process D (tau 33ms) completed I/O; added to ready queue[Q C H I D F]
time 18481ms: Process G completed a CPU Burst; 49 bursts to go [Q C H I D F]
time 18481ms: Recalculate tau = 26ms for Process G [Q C H I D F]
time 18481ms: Process G switching out of CPU; will block on I/O until time 18504ms
time 18485ms: Process C started using the CPU for 68ms burst [Q H I D F]
time 18504ms: Process G (tau 26ms) completed I/O; added to ready queue[Q H I D F G]
time 18553ms: Process C completed a CPU Burst; 55 bursts to go [Q H I D F G]
time 18553ms: Recalculate tau = 73ms for Process C [Q H I D F G]
time 18553ms: Process C switching out of CPU; will block on I/O until time 18613ms
time 18557ms: Process H started using the CPU for 19ms burst [Q I D F G]
time 18576ms: Process H completed a CPU Burst; 54 bursts to go [Q I D F G]
time 18576ms: Recalculate tau = 18ms for Process H [Q I D F G]
time 18576ms: Process H switching out of CPU; will block on I/O until time 18637ms
time 18580ms: Process I started using the CPU for 29ms burst [Q D F G]
time 18609ms: Process I completed a CPU Burst; 35 bursts to go [Q D F G]
time 18609ms: Recalculate tau = 40ms for Process I [Q D F G]
time 18609ms: Process I switching out of CPU; will block on I/O until time 18655ms
time 18613ms: Process D started using the CPU for 148ms burst [Q F G C]
time 18613ms: Process C (tau 73ms) completed I/O; added to ready queue[Q F G C]
time 18637ms: Process H (tau 18ms) completed I/O; added to ready queue[Q F G C H]
time 18655ms: Process I (tau 40ms) completed I/O; added to ready queue[Q F G C H I]
